Workbook
Name \0: #REF!
Name \b: #N/A
Name \C: #REF!
Name \C: #REF!
Name \C: #REF!
Name \C: #REF!
Name \c1: #REF!
Name \c1: #REF!
Name \c1: #REF!
Name \c1: #REF!
Name \c2: #REF!
Name \c2: #REF!
Name \c2: #REF!
Name \c2: #REF!
Name \D: #REF!
Name \D: #REF!
Name \D: #REF!
Name \D: #REF!
Name \l: #REF!
Name \l: #REF!
Name \l: #REF!
Name \l: #REF!
Name \M: #REF!
Name \M: #REF!
Name \M: #REF!
Name \M: #REF!
Name \N: #REF!
Name \N: #REF!
Name \N: #REF!
Name \N: #REF!
Name \p: #REF!
Name \p: #REF!
Name \p: #REF!
Name \p: #REF!
Name \R: #REF!
Name \R: #REF!
Name \R: #REF!
Name \R: #REF!
Name \S: #REF!
Name \S: #REF!
Name \S: #REF!
Name \S: #REF!
Name \U: #REF!
Name \U: #REF!
Name \U: #REF!
Name \U: #REF!
Name \V: #REF!
Name \V: #REF!
Name \V: #REF!
Name \V: #REF!
Name \x: #REF!
Name \x: #REF!
Name \x: #REF!
Name \x: #REF!
Name _: "tcap"
Name _\wdr: #REF!
Name _\wdr: #REF!
Name _\wdr: #REF!
Name _\wdr: #REF!
Name __________________________________aaa5: #REF!

Sheet BOQ
A1: Construction of check dam across Marudhaiyar river at Varanavasi village in Ariyalur Taluk and District
A2: BOQ Abstract
A3: Sno | B3: Item Description | C3: Quantity | D3: Units | E3: Basic Rate | F3: Amount
A4: 1 | B4: Clearing Scrub jungle and destroying them effectively etc. complete complying with Standard Specifications and as directed by the Departmental Engineers. | C4: 25849.6 | D4: sqm | E4: 6 | F4: =C4*E4 -> 155097.6
A5: 2 | B5: Earthwork excavation for foundation in all kind of soils and sub soils to full depth except hardrock,medium rock,requiring blasting inclusive of shoring,strutting and bailing out water wherever necessary,refilling the sides of foundation with excavated earth in layers of not more than 15cm thick well rammed and compacted and depositing the surplus excavated earth in places shown by the departmental officers with initial lead of 10 meters and initial lift of 2 meters clearing and levelling the site complete complying with standard specifications and as directed by the Departmental Engineers. (Narrow excavation) | C5: 5254 | D5: cum | E5: 226 | F5: =C5*E5 -> 1187404
A6: 3 | B6: Earth work excavating and depositing on bank with initial lead of 10 metres and lift of 2 metres in sand silt or other loose soil, wet sand or silt not under water light black cotton soil sandy loam and ordinary soil including excavated earth ordinary soil etc. complete complying with Standard Specifications and as directed by the Departmental Engineers.SS 20 A. (Open Excavation.) | C6: 29381 | D6: cum | E6: 85 | F6: =C6*E6 -> 2497385
A7: 4 | B7: Supplying and erection of steel centering for sides and soffits with strutting up to 3m height for plain surface with all cross bracings using Mild Steel sheets of size 90cm. X 60cm. thickness of and B.G.10 stiffened with welded Mild Steel angles of size 25 X 25 X 3mm for boarding, laid over country wood joists of size 10cmX 6.5cm spaced at 90cm. Centre to centre and supported by casuarina props of 10 to 13cm dia (spaced at 75cm) Centre to centre etc. complete complying with Standard Specifications and as directed by the Departmental Engineers. | F7: =C7*E7 -> 0
A8: 4.01 | B8: Centering without strutting Below ground level | C8: 6346 | D8: sqm | E8: 955 | F8: =C8*E8 -> 6060430
A9: 4.02 | B9: Centering with strutting upto 3m height | C9: 6536 | D9: sqm | E9: 1060 | F9: =C9*E9 -> 6928160
A10: 4.03 | B10: Centering with strutting 3-4m height | C10: 739 | D10: sqm | E10: 1095 | F10: =C10*E10 -> 809205
A11: 4.04 | B11: Centering with strutting 4-5m height | C11: 303 | D11: sqm | E11: 1130 | F11: =C11*E11 -> 342390
A12: 5 | B12: Providing and placing Plain cement concrete M10 grade using crushed broken hard granite course aggregate (well Graded) of Nominal maximum size of 40mm to Ls specified grading (to achieve the specified characteristicik strength of 10N /mm2 in 28 days) and mixing the ingredients in approved mixer including dewatering of the placement site by baling (pumping and dewatering wherever necess eng placing in layers and vibrating water curing finishing hte surface with all leades and lifts etc. complete complying with Standard Specifications and as directed by the Departmental Engineers. | C12: 379 | D12: cum | E12: 5885 | F12: =C12*E12 -> 2230415
A13: 6 | B13: Providing and placing in position of plain cement concrete M15 using 20 mm size hard blue granite broken stone jelly with M.Sand mixing with mixer machine including the cost of bailing/pumping wherever necessary laying the concrete in layers of not exceeding 15 cm thick, compacting, consolidation, vibratring,finishing, watering, curing etc. complete complying with Standard Specifications and as directed by the Departmental Engineers. | F13: =C13*E13 -> 0
A14: 6.01 | B14: Below ground level upto 1.50 m | C14: 739 | D14: cum | E14: 6850 | F14: =C14*E14 -> 5062150
A15: 6.02 | B15: Below ground level-Foundation upto 1.50 m to 4.50 m | C15: 220 | D15: cum | E15: 6984 | F15: =C15*E15 -> 1536480
A16: 7 | B16: Providing and placing in position of plain cement concrete M15 grade using 60% of 40mm size hard blue granite broken stone jelly and 40% of 20mm size hard blue granite broken stone jelly with M.Sand mixing with mixer machine including the cost of bailing/pumping wherever necessary laying the concrete in layers of not exceeding 15 cm thick, compacting, consolidation,vibrating,finishing, watering, curing etc. complete complying with Standard Specifications and as directed by the Departmental Engineers. | F16: =C16*E16 -> 0
A17: 7.01 | B17: Below ground level up to 1.50 m | C17: 4986 | D17: cum | E17: 6510 | F17: =C17*E17 -> 32458860
A18: 7.02 | B18: Above ground level up to 4.50 m | C18: 1579 | D18: cum | E18: 6645 | F18: =C18*E18 -> 10492455
A19: 8 | B19: Supplying and fabrication and CC Block of size 1.50 X 1.50 X 0.90 m with Plain Cement Concrete 1:2:4 (one cement two m.sand and Four aggregate) using 40mm and down graded metal hard broken stone jelly for foundation including dewatering if found necessary and placing in position including ramming watering and curing etc. complete complying with Standard Specifications and as directed by the Departmental Engineers. | C19: 800 | D19: Nos | E19: 14577 | F19: =C19*E19 -> 11661600
A20: 9 | B20: Providing and laying in position standardised concrete Mix M-20 Grade in accordance with IS 456-2000 using 20mm and downgraded hard broken granite stone jelly for all RCC items of works with minium cement content of 325 kg/m3 and maxium water cement ratio of 0.55 including admixture (Plasticizer/Super plasticizer) in recommended proportions asper IS 9103 to accelerate, retard setting of concrete, improve workability without imparing strength and durability with about (5 cu.m) 7730 kg of 20 mm machine crushed stone jelly and with about (4.79 cu.m) 7670 kg of m.sand, but excluding cost of reinforcemnt grill and fabricating charges, centering and shuttering and also including and laying, vibrating with mechanical vibrators, finishing, curing etc. complete complying with Standard Specifications and as directed by the Departmental Engineers. | C20: 906 | D20: cum | E20: 8709 | F20: =C20*E20 -> 7890354
A21: 10 | B21: Reinforced cement concrete M25 using 20mm hard broken stone jelly and downgreded to IS specified grading mixed in mixer machine including dewatering the placement site, laying the concrete in layers and in bays.vibrating compacting and finishing the surface with all lead and lifts, watering curing complete to attain the profile and strength as specified in the drawings and specification for various lengths and heights below and above ground level etc. complete complying with Standard Specifications and as directed by the Departmental Engineers. | C21: 32 | D21: cum | E21: 8857 | F21: =C21*E21 -> 283424
A22: 11 | B22: Providing and placing plain cement concrete M20 grade using crusher broken hard granite course agrregate (well graded) of nominal maximum size of 20mm to specified grading to achieve the special characteristic strength of 20 N/mm2 in 28 days and mixing the ingredients in approved mixed placing in layers and vibrating water curing finishing the surface with all leads and lifts etc. complete in all respects so as to attain the profile strength specified in the approved drawing and specified in the approved drawing and specifications as per the direction of the engineer incharge of works and etc. complete complying with Standard Specifications and as directed by the Departmental Engineers. | F22: =C22*E22 -> 0
A23: 11.01 | B23: Below ground level up to 1.50 m | C23: 225 | D23: cum | E23: 7280 | F23: =C23*E23 -> 1638000
A24: 11.02 | B24: Below ground level 1.50m to upto 4.50 m | C24: 525 | D24: cum | E24: 7414 | F24: =C24*E24 -> 3892350
A25: 11.03 | B25: Above ground level upto 4.50m | C25: 2.9 | D25: cum | E25: 7416 | F25: =C25*E25 -> 21506.4
A26: 12 | B26: Supplying fabricating and placing in position of Mild Steel (MS) or Ribbed Tor Steel (RTS) of grills for all R C C works including cost of steel, binding wire and labour charges for decoiling cutting, bending and tying the grills etc. complete complying with standard specifications and as directed by the Departmental Engineers. | C26: 1752 | D26: qtl. | E26: 9258 | F26: =C26*E26 -> 16220016
A27: 13 | B27: Supplying and filling in clean M- sand in layers of not more than 15cm thick well rammed watered and consolidated etc. complete complying with Standard Specifications and as directed by the Departmental Engineers. | C27: 398 | D27: cum | E27: 1785 | F27: =C27*E27 -> 710430
A28: 14 | B28: Supplying and filling for inverted filter arrangements below CC blocks with 40 cm thick graded inverted filter provided in two or more layers (ie 20 mm, 40 mm, 63 mm.) size metal provided using HBGS jelly conveyance upto 100 m etc. complete complying with Standard Specifications and as directed by the Departmental Engineers. | C28: 795 | D28: cum | E28: 1580 | F28: =C28*E28 -> 1256100
A29: 15 | B29: Supplying and Filling of Gravel in between the gap of CC Block with 75mm thick,etc. complete complying with Standard Specifications and as directed by the Departmental Engineers. | C29: 345 | D29: cum | E29: 447 | F29: =C29*E29 -> 154215
A30: 16 | B30: Supplying and filling loose boulders of Size more than 300mm and weight more than 40kg in U/S and D/S apron using including conveyance,cost of materials etc. complete complying with standard specifications and as directed by the Departmental Engineers | C30: 4440 | D30: cum | E30: 2614 | F30: =C30*E30 -> 11606160
A31: 17 | B31: Rough stone dry packing using new stones for cone wrapping aprons and revetment including labour charges etc. complete complying with Standard Specifications and as directed by the Departmental Engineers. (.Cone Wrapping) | C31: 1099 | D31: cum | E31: 2315 | F31: =C31*E31 -> 2544185
A32: 18 | B32: Jeddy stone packing using new stones u/s stone pitching including labour charges etc. complete complying with Standard Specifications and as directed by the Departmental Engineers. | C32: 450 | D32: cum | E32: 2614 | F32: =C32*E32 -> 1176300
A33: 19 | B33: Design, fabrication, supply, errection, testing and commissioning of fixed wheel type vertical lift gate(with top seal) consisting of skin plate, stiffeners, horizontal and vertical girders, wheels, guide rollers, rubber seals etc., with all accessories for canal escape/regulator vent including cost of materials, machinery, labour, cutting, aligning, welding, finishing, cleaning, applying one coat of zinc rich epoxy primer and three coats of cold applied coal tar epoxy paint,seal fixing etc., complete as per specifications and approved drawings with lead up to 1km and all lifts for structural steel components and all leads and all lifts including packing/forwarding charges for other materials. | C33: 4.44 | D33: tonne | E33: 233491 | F33: =C33*E33 -> 1036700
A34: 20 | B34: Design, fabrication, supply, errection, testing and commissioning of supporting structure, platform, railing, ladder etc., with all accessories for operating canal escape/regulator gate including cost of all materials, machinery, labour, cutting, aligning, welding, finishing, cleaning, greasing, applying two coats of zinc chromate red oxide primer and three coats of approved synthetic enamel paint etc., complete as per specifications and approved drawings with lead up to 1km and all lifts for structural steel components and all leads and all lifts including packing/forwarding charges for other materials. | C34: 3.6 | D34: tonne | E34: 59143 | F34: =C34*E34 -> 212914.8
... A42: 28 | B42: Supplying Demarcation RCC Pre cast Post in Cement Concrete of Grade M15 with well graded aggregates and the nominal maximum size of course aggregate of size 20 mm of size 0.20 x 0.20 x 1.45 M and fixing the Post 40 Cm depth below Ground level, the Post includes using 4 Nos of 10mm RTS Main rod to a length of 1.325 M, using 8 mm MS 10 Nos as Strips with Steel Centring and Painting the Post with Enamel Paint to a Height of 0.80 m around the post etc., complete and Conveying the post to the Site of Demarcation Boundary such as Tank Bund and foreshore including earthwork excavation for Foundation in HSC having the base Plain cement Concrete of 10 Cm of cement concrete M7.5 using Hard blue granite broken stone of graded metal of 40 mm and the Post embeded using Cement Concrete of Grade Cement Concrete M10 with well graded aggregates and the Nominal maximum size of course aggregate of 20 mm etc., complete as directed by the Engineer in charge of works and as per the Technical Specfications | C42: 150 | D42: Nos | E42: 1697 | F42: =C42*E42 -> 254550
B43: Total = | F43: =SUM(F4:F42) -> 1.9847417e+08
B44: GST at 18% = | E44: 0 | F44: =F43*0.18 -> 35725351
B45: Grand Total = | F45: =SUM(F43:F44) -> 2.3419952e+08
F49: =F45+6807707 -> 2.4100723e+08
F50: =F49-F45 -> 6807707
...

Sheet BOQ Major
A1: Construction of check dam across Marudhaiyar river at Varanavasi village in Ariyalur Taluk and District | G1: % from Total Value
A2: BOQ Abstract - Major items
A3: Sno | B3: Item Description | C3: Quantity | D3: Units | E3: Basic Rate | F3: Amount
A4: 1 | B4: Clearing Scrub jungle and destroying them effectively etc. complete complying with Standard Specifications and as directed by the Departmental Engineers. | C4: 25849.6 | D4: sqm | E4: 6 | F4: =C4*E4 -> 155097.6 | G4: =F4/$F$43 -> 0.00078144979
A5: 2 | B5: Earthwork excavation for foundation in all kind of soils and sub soils to full depth except hardrock,medium rock,requiring blasting inclusive of shoring,strutting and bailing out water wherever necessary,refilling the sides of foundation with excavated earth in layers of not more than 15cm thick well rammed and compacted and depositing the surplus excavated earth in places shown by the departmental officers with initial lead of 10 meters and initial lift of 2 meters clearing and levelling the site complete complying with standard specifications and as directed by the Departmental Engineers. (Narrow excavation) | C5: 5254 | D5: cum | E5: 226 | F5: =C5*E5 -> 1187404 | G5: =F5/$F$43 -> 0.0059826626
A6: 3 | B6: Earth work excavating and depositing on bank with initial lead of 10 metres and lift of 2 metres in sand silt or other loose soil, wet sand or silt not under water light black cotton soil sandy loam and ordinary soil including excavated earth ordinary soil etc. complete complying with Standard Specifications and as directed by the Departmental Engineers.SS 20 A. (Open Excavation.) | C6: 29381 | D6: cum | E6: 85 | F6: =C6*E6 -> 2497385 | G6: =F6/$F$43 -> 0.012582922
A7: 4 | B7: Supplying and erection of steel centering for sides and soffits with strutting up to 3m height for plain surface with all cross bracings using Mild Steel sheets of size 90cm. X 60cm. thickness of and B.G.10 stiffened with welded Mild Steel angles of size 25 X 25 X 3mm for boarding, laid over country wood joists of size 10cmX 6.5cm spaced at 90cm. Centre to centre and supported by casuarina props of 10 to 13cm dia (spaced at 75cm) Centre to centre etc. complete complying with Standard Specifications and as directed by the Departmental Engineers. | F7: =C7*E7 -> 0 | G7: =F7/$F$43 -> 0
A8: 4.01 | B8: Centering without strutting Below ground level | C8: 6346 | D8: sqm | E8: 955 | F8: =C8*E8 -> 6060430 | G8: =F8/$F$43 -> 0.030535107
A9: 4.02 | B9: Centering with strutting upto 3m height | C9: 6536 | D9: sqm | E9: 1060 | F9: =C9*E9 -> 6928160 | G9: =F9/$F$43 -> 0.034907111
A10: 4.03 | B10: Centering with strutting 3-4m height | C10: 739 | D10: sqm | E10: 1095 | F10: =C10*E10 -> 809205 | G10: =F10/$F$43 -> 0.00407713
A11: 4.04 | B11: Centering with strutting 4-5m height | C11: 303 | D11: sqm | E11: 1130 | F11: =C11*E11 -> 342390 | G11: =F11/$F$43 -> 0.0017251111
A12: 5 | B12: Providing and placing Plain cement concrete M10 grade using crushed broken hard granite course aggregate (well Graded) of Nominal maximum size of 40mm to Ls specified grading (to achieve the specified characteristicik strength of 10N /mm2 in 28 days) and mixing the ingredients in approved mixer including dewatering of the placement site by baling (pumping and dewatering wherever necess eng placing in layers and vibrating water curing finishing hte surface with all leades and lifts etc. complete complying with Standard Specifications and as directed by the Departmental Engineers. | C12: 379 | D12: cum | E12: 5885 | F12: =C12*E12 -> 2230415 | G12: =F12/$F$43 -> 0.01123781
A13: 6 | B13: Providing and placing in position of plain cement concrete M15 using 20 mm size hard blue granite broken stone jelly with M.Sand mixing with mixer machine including the cost of bailing/pumping wherever necessary laying the concrete in layers of not exceeding 15 cm thick, compacting, consolidation, vibratring,finishing, watering, curing etc. complete complying with Standard Specifications and as directed by the Departmental Engineers. | F13: =C13*E13 -> 0 | G13: =F13/$F$43 -> 0
A14: 6.01 | B14: Below ground level upto 1.50 m | C14: 739 | D14: cum | E14: 6850 | F14: =C14*E14 -> 5062150 | G14: =F14/$F$43 -> 0.025505334
A15: 6.02 | B15: Below ground level-Foundation upto 1.50 m to 4.50 m | C15: 220 | D15: cum | E15: 6984 | F15: =C15*E15 -> 1536480 | G15: =F15/$F$43 -> 0.0077414607
A16: 7 | B16: Providing and placing in position of plain cement concrete M15 grade using 60% of 40mm size hard blue granite broken stone jelly and 40% of 20mm size hard blue granite broken stone jelly with M.Sand mixing with mixer machine including the cost of bailing/pumping wherever necessary laying the concrete in layers of not exceeding 15 cm thick, compacting, consolidation,vibrating,finishing, watering, curing etc. complete complying with Standard Specifications and as directed by the Departmental Engineers. | F16: =C16*E16 -> 0 | G16: =F16/$F$43 -> 0
A17: 7.01 | B17: Below ground level up to 1.50 m | C17: 4986 | D17: cum | E17: 6510 | F17: =C17*E17 -> 32458860 | G17: =F17/$F$43 -> 0.16354199
A18: 7.02 | B18: Above ground level up to 4.50 m | C18: 1579 | D18: cum | E18: 6645 | F18: =C18*E18 -> 10492455 | G18: =F18/$F$43 -> 0.052865594
A19: 8 | B19: Supplying and fabrication and CC Block of size 1.50 X 1.50 X 0.90 m with Plain Cement Concrete 1:2:4 (one cement two m.sand and Four aggregate) using 40mm and down graded metal hard broken stone jelly for foundation including dewatering if found necessary and placing in position including ramming watering and curing etc. complete complying with Standard Specifications and as directed by the Departmental Engineers. | C19: 800 | D19: Nos | E19: 14577 | F19: =C19*E19 -> 11661600 | G19: =F19/$F$43 -> 0.05875626
A20: 9 | B20: Providing and laying in position standardised concrete Mix M-20 Grade in accordance with IS 456-2000 using 20mm and downgraded hard broken granite stone jelly for all RCC items of works with minium cement content of 325 kg/m3 and maxium water cement ratio of 0.55 including admixture (Plasticizer/Super plasticizer) in recommended proportions asper IS 9103 to accelerate, retard setting of concrete, improve workability without imparing strength and durability with about (5 cu.m) 7730 kg of 20 mm machine crushed stone jelly and with about (4.79 cu.m) 7670 kg of m.sand, but excluding cost of reinforcemnt grill and fabricating charges, centering and shuttering and also including and laying, vibrating with mechanical vibrators, finishing, curing etc. complete complying with Standard Specifications and as directed by the Departmental Engineers. | C20: 906 | D20: cum | E20: 8709 | F20: =C20*E20 -> 7890354 | G20: =F20/$F$43 -> 0.039755067
A21: 10 | B21: Reinforced cement concrete M25 using 20mm hard broken stone jelly and downgreded to IS specified grading mixed in mixer machine including dewatering the placement site, laying the concrete in layers and in bays.vibrating compacting and finishing the surface with all lead and lifts, watering curing complete to attain the profile and strength as specified in the drawings and specification for various lengths and heights below and above ground level etc. complete complying with Standard Specifications and as directed by the Departmental Engineers. | C21: 32 | D21: cum | E21: 8857 | F21: =C21*E21 -> 283424 | G21: =F21/$F$43 -> 0.0014280145
A22: 11 | B22: Providing and placing plain cement concrete M20 grade using crusher broken hard granite course agrregate (well graded) of nominal maximum size of 20mm to specified grading to achieve the special characteristic strength of 20 N/mm2 in 28 days and mixing the ingredients in approved mixed placing in layers and vibrating water curing finishing the surface with all leads and lifts etc. complete in all respects so as to attain the profile strength specified in the approved drawing and specified in the approved drawing and specifications as per the direction of the engineer incharge of works and etc. complete complying with Standard Specifications and as directed by the Departmental Engineers. | F22: =C22*E22 -> 0 | G22: =F22/$F$43 -> 0
A23: 11.01 | B23: Below ground level up to 1.50 m | C23: 225 | D23: cum | E23: 7280 | F23: =C23*E23 -> 1638000 | G23: =F23/$F$43 -> 0.0082529631
A24: 11.02 | B24: Below ground level 1.50m to upto 4.50 m | C24: 525 | D24: cum | E24: 7414 | F24: =C24*E24 -> 3892350 | G24: =F24/$F$43 -> 0.019611368
A25: 11.03 | B25: Above ground level upto 4.50m | C25: 2.9 | D25: cum | E25: 7416 | F25: =C25*E25 -> 21506.4 | G25: =F25/$F$43 -> 0.00010835868
A26: 12 | B26: Supplying fabricating and placing in position of Mild Steel (MS) or Ribbed Tor Steel (RTS) of grills for all R C C works including cost of steel, binding wire and labour charges for decoiling cutting, bending and tying the grills etc. complete complying with standard specifications and as directed by the Departmental Engineers. | C26: 1752 | D26: qtl. | E26: 9258 | F26: =C26*E26 -> 16220016 | G26: =F26/$F$43 -> 0.081723561
A27: 13 | B27: Supplying and filling in clean M- sand in layers of not more than 15cm thick well rammed watered and consolidated etc. complete complying with Standard Specifications and as directed by the Departmental Engineers. | C27: 398 | D27: cum | E27: 1785 | F27: =C27*E27 -> 710430 | G27: =F27/$F$43 -> 0.0035794582
A28: 14 | B28: Supplying and filling for inverted filter arrangements below CC blocks with 40 cm thick graded inverted filter provided in two or more layers (ie 20 mm, 40 mm, 63 mm.) size metal provided using HBGS jelly conveyance upto 100 m etc. complete complying with Standard Specifications and as directed by the Departmental Engineers. | C28: 795 | D28: cum | E28: 1580 | F28: =C28*E28 -> 1256100 | G28: =F28/$F$43 -> 0.0063287832
A29: 15 | B29: Supplying and Filling of Gravel in between the gap of CC Block with 75mm thick,etc. complete complying with Standard Specifications and as directed by the Departmental Engineers. | C29: 345 | D29: cum | E29: 447 | F29: =C29*E29 -> 154215 | G29: =F29/$F$43 -> 0.00077700287
A30: 16 | B30: Supplying and filling loose boulders of Size more than 300mm and weight more than 40kg in U/S and D/S apron using including conveyance,cost of materials etc. complete complying with standard specifications and as directed by the Departmental Engineers | C30: 4440 | D30: cum | E30: 2614 | F30: =C30*E30 -> 11606160 | G30: =F30/$F$43 -> 0.058476929
A31: 17 | B31: Rough stone dry packing using new stones for cone wrapping aprons and revetment including labour charges etc. complete complying with Standard Specifications and as directed by the Departmental Engineers. (.Cone Wrapping) | C31: 1099 | D31: cum | E31: 2315 | F31: =C31*E31 -> 2544185 | G31: =F31/$F$43 -> 0.012818721
A32: 18 | B32: Jeddy stone packing using new stones u/s stone pitching including labour charges etc. complete complying with Standard Specifications and as directed by the Departmental Engineers. | C32: 450 | D32: cum | E32: 2614 | F32: =C32*E32 -> 1176300 | G32: =F32/$F$43 -> 0.0059267158
A33: 19 | B33: Design, fabrication, supply, errection, testing and commissioning of fixed wheel type vertical lift gate(with top seal) consisting of skin plate, stiffeners, horizontal and vertical girders, wheels, guide rollers, rubber seals etc., with all accessories for canal escape/regulator vent including cost of materials, machinery, labour, cutting, aligning, welding, finishing, cleaning, applying one coat of zinc rich epoxy primer and three coats of cold applied coal tar epoxy paint,seal fixing etc., complete as per specifications and approved drawings with lead up to 1km and all lifts for structural steel components and all leads and all lifts including packing/forwarding charges for other materials. | C33: 4.44 | D33: tonne | E33: 233491 | F33: =C33*E33 -> 1036700 | G33: =F33/$F$43 -> 0.0052233499
A34: 20 | B34: Design, fabrication, supply, errection, testing and commissioning of supporting structure, platform, railing, ladder etc., with all accessories for operating canal escape/regulator gate including cost of all materials, machinery, labour, cutting, aligning, welding, finishing, cleaning, greasing, applying two coats of zinc chromate red oxide primer and three coats of approved synthetic enamel paint etc., complete as per specifications and approved drawings with lead up to 1km and all lifts for structural steel components and all leads and all lifts including packing/forwarding charges for other materials. | C34: 3.6 | D34: tonne | E34: 59143 | F34: =C34*E34 -> 212914.8 | G34: =F34/$F$43 -> 0.0010727582
... A42: 28 | B42: Supplying Demarcation RCC Pre cast Post in Cement Concrete of Grade M15 with well graded aggregates and the nominal maximum size of course aggregate of size 20 mm of size 0.20 x 0.20 x 1.45 M and fixing the Post 40 Cm depth below Ground level, the Post includes using 4 Nos of 10mm RTS Main rod to a length of 1.325 M, using 8 mm MS 10 Nos as Strips with Steel Centring and Painting the Post with Enamel Paint to a Height of 0.80 m around the post etc., complete and Conveying the post to the Site of Demarcation Boundary such as Tank Bund and foreshore including earthwork excavation for Foundation in HSC having the base Plain cement Concrete of 10 Cm of cement concrete M7.5 using Hard blue granite broken stone of graded metal of 40 mm and the Post embeded using Cement Concrete of Grade Cement Concrete M10 with well graded aggregates and the Nominal maximum size of course aggregate of 20 mm etc., complete as directed by the Engineer in charge of works and as per the Technical Specfications | C42: 150 | D42: Nos | E42: 1697 | F42: =C42*E42 -> 254550 | G42: =F42/$F$43 -> 0.0012825346
B43: Total = | F43: =SUM(F4:F42) -> 1.9847417e+08 | G43: =F43/$F$43 -> 1
B44: GST at 18% = | E44: 0 | F44: =F43*0.18 -> 35725351
B45: Grand Total = | F45: =SUM(F43:F44) -> 2.3419952e+08
F49: =F45+6807707 -> 2.4100723e+08
F50: =F49-F45 -> 6807707
...

Sheet Top Sheet
B2: ZERO COST ESTIMATE - SUMMARY
C3: Project: | D3: =BOQ!A1 -> Construction of check dam across Marudhaiyar river at Varanavasi village in Ariyalur Taluk and District
C4: Client: | D4: WRO
C5: Location: | D5: Pattukkottai Taluk
C6: Contractual Completion Duration: | D6: 12 months
C7: Considered Completion Duration: | D7: 12 months
B9: Sl. No. | C9: Description | F9: Amount (in Rs)
B11: 1 | C11: COSTS
B12: a) | C12: Direct Cost | F12: ='BOQ Split'!N43 -> 1.2975679e+08
B13: b) | C13: Indirect Cost | D13: OH | E13: 10476 | F13: =IDC!G77 -> 8768170.9 | J13: =13750*11 -> 151250
B14: 2 | C14: TOTAL COST (DC+IDC) | F14: =SUM(F12:F13) -> 1.3852496e+08
B16: 3 | C16: CONTRACT VALUE (SALES) | D16: (Excluding GST & LC) | F16: ='BOQ Split'!F43 -> 1.9847417e+08
B18: 4 | C18: GROSS MARGIN | F18: =+F16-F14 -> 59949214
B20: 5 | C20: ESCALATION BENEFITS @ 2% | F20: =F12*0% -> 0
B22: 6 | C22: TOTAL MARGIN (4+5) | F22: =SUM(F18:F20) -> 59949214
B24: 7 | C24: Risk & Contingency | F24: 0.01
B25: 8 | C25: Interest Charges | F25: 0
B26: 9 | C26: Insurance Charges | F26: 0
B27: 10 | C27: Bank Guarantee | F27: 0
B29: 11 | C29: GM % | F29: =+F22/F16-F24-F25-F26-F27 -> 0.29205046
B30: 12 | C30: Others
C31: HO Overheads | F31: 0.02
B33: 13 | C33: PBT | F33: =F29-SUM(F31:F31) -> 0.27205046
B38: Remarks:
B40: Prepared by: | E40: Reviewed by:

Sheet BOQ Split
A1: Construction of check dam across Marudhaiyar river at Varanavasi village in Ariyalur Taluk and District
A2: BOQ Abstract
A3: Sno | B3: Item Description | C3: Quantity | D3: Units | E3: Basic Rate | F3: Amount | H3: Materials | I3: Machinery | J3: Fuel | K3: S/C | L3: Labour | M3: Total Rate | N3: Amount | O3: Variance | P3: Materials | Q3: Machinery | R3: Fuel | S3: S/C | T3: Labour
A4: 1 | B4: Clearing Scrub jungle and destroying them effectively etc. complete complying with Standard Specifications and as directed by the Departmental Engineers. | C4: 25849.6 | D4: sqm | E4: 6 | F4: =C4*E4 -> 155097.6 | I4: =RA!F10 -> 7.8159222 | J4: =RA!F13 -> 3.4092597 | L4: =RA!F16 -> 0.46035529 | M4: =SUM(H4:L4) -> 11.685537 | N4: =M4*C4 -> 302066.46 | O4: =F4-N4 -> -146968.86 | P4: =H4*C4 -> 0 | Q4: =I4*C4 -> 202038.46 | R4: =J4*C4 -> 88128 | S4: =K4*C4 -> 0 | T4: =L4*C4 -> 11900
A5: 2 | B5: Earthwork excavation for foundation in all kind of soils and sub soils to full depth except hardrock,medium rock,requiring blasting inclusive of shoring,strutting and bailing out water wherever necessary,refilling the sides of foundation with excavated earth in layers of not more than 15cm thick well rammed and compacted and depositing the surplus excavated earth in places shown by the departmental officers with initial lead of 10 meters and initial lift of 2 meters clearing and levelling the site complete complying with standard specifications and as directed by the Departmental Engineers. (Narrow excavation) | C5: 5254 | D5: cum | E5: 226 | F5: =C5*E5 -> 1187404 | I5: =RA!F26 -> 122.98322 | J5: =RA!F29 -> 105.24553 | L5: =RA!F32 -> 15.987819 | M5: =SUM(H5:L5) -> 244.21657 | N5: =M5*C5 -> 1283113.8 | O5: =F5-N5 -> -95709.846 | P5: =H5*C5 -> 0 | Q5: =I5*C5 -> 646153.85 | R5: =J5*C5 -> 552960 | S5: =K5*C5 -> 0 | T5: =L5*C5 -> 84000
A6: 3 | B6: Earth work excavating and depositing on bank with initial lead of 10 metres and lift of 2 metres in sand silt or other loose soil, wet sand or silt not under water light black cotton soil sandy loam and ordinary soil including excavated earth ordinary soil etc. complete complying with Standard Specifications and as directed by the Departmental Engineers.SS 20 A. (Open Excavation.) | C6: 29381 | D6: cum | E6: 85 | F6: =C6*E6 -> 2497385 | I6: =RA!F42 -> 21.992235 | J6: =RA!F45 -> 21.957047 | L6: =RA!F48 -> 2.8589905 | M6: =SUM(H6:L6) -> 46.808272 | N6: =M6*C6 -> 1375273.8 | O6: =F6-N6 -> 1122111.2 | P6: =H6*C6 -> 0 | Q6: =I6*C6 -> 646153.85 | R6: =J6*C6 -> 645120 | S6: =K6*C6 -> 0 | T6: =L6*C6 -> 84000
A7: 4 | B7: Supplying and erection of steel centering for sides and soffits with strutting up to 3m height for plain surface with all cross bracings using Mild Steel sheets of size 90cm. X 60cm. thickness of and B.G.10 stiffened with welded Mild Steel angles of size 25 X 25 X 3mm for boarding, laid over country wood joists of size 10cmX 6.5cm spaced at 90cm. Centre to centre and supported by casuarina props of 10 to 13cm dia (spaced at 75cm) Centre to centre etc. complete complying with Standard Specifications and as directed by the Departmental Engineers. | F7: =C7*E7 -> 0 | M7: =SUM(H7:L7) -> 0 | N7: =M7*C7 -> 0 | O7: =F7-N7 -> 0 | P7: =H7*C7 -> 0 | Q7: =I7*C7 -> 0 | R7: =J7*C7 -> 0 | S7: =K7*C7 -> 0 | T7: =L7*C7 -> 0
A8: 4.01 | B8: Centering without strutting Below ground level | C8: 6346 | D8: sqm | E8: 955 | F8: =C8*E8 -> 6060430 | K8: =RA!F55 -> 494.96 | L8: =K8*0.05 -> 24.748 | M8: =SUM(H8:L8) -> 519.708 | N8: =M8*C8 -> 3298067 | O8: =F8-N8 -> 2762363 | P8: =H8*C8 -> 0 | Q8: =I8*C8 -> 0 | R8: =J8*C8 -> 0 | S8: =K8*C8 -> 3141016.2 | T8: =L8*C8 -> 157050.81
A9: 4.02 | B9: Centering with strutting upto 3m height | C9: 6536 | D9: sqm | E9: 1060 | F9: =C9*E9 -> 6928160 | K9: =RA!F61 -> 602.56 | L9: =K9*0.05 -> 30.128 | M9: =SUM(H9:L9) -> 632.688 | N9: =M9*C9 -> 4135248.8 | O9: =F9-N9 -> 2792911.2 | P9: =H9*C9 -> 0 | Q9: =I9*C9 -> 0 | R9: =J9*C9 -> 0 | S9: =K9*C9 -> 3938332.2 | T9: =L9*C9 -> 196916.61
A10: 4.03 | B10: Centering with strutting 3-4m height | C10: 739 | D10: sqm | E10: 1095 | F10: =C10*E10 -> 809205 | K10: =RA!F61 -> 602.56 | L10: =K10*0.05 -> 30.128 | M10: =SUM(H10:L10) -> 632.688 | N10: =M10*C10 -> 467556.43 | O10: =F10-N10 -> 341648.57 | P10: =H10*C10 -> 0 | Q10: =I10*C10 -> 0 | R10: =J10*C10 -> 0 | S10: =K10*C10 -> 445291.84 | T10: =L10*C10 -> 22264.592
A11: 4.04 | B11: Centering with strutting 4-5m height | C11: 303 | D11: sqm | E11: 1130 | F11: =C11*E11 -> 342390 | K11: =RA!F67 -> 656.36 | L11: =K11*0.05 -> 32.818 | M11: =SUM(H11:L11) -> 689.178 | N11: =M11*C11 -> 208820.93 | O11: =F11-N11 -> 133569.07 | P11: =H11*C11 -> 0 | Q11: =I11*C11 -> 0 | R11: =J11*C11 -> 0 | S11: =K11*C11 -> 198877.08 | T11: =L11*C11 -> 9943.854
A12: 5 | B12: Providing and placing Plain cement concrete M10 grade using crushed broken hard granite course aggregate (well Graded) of Nominal maximum size of 40mm to Ls specified grading (to achieve the specified characteristicik strength of 10N /mm2 in 28 days) and mixing the ingredients in approved mixer including dewatering of the placement site by baling (pumping and dewatering wherever necess eng placing in layers and vibrating water curing finishing hte surface with all leades and lifts etc. complete complying with Standard Specifications and as directed by the Departmental Engineers. | C12: 379 | D12: cum | E12: 5885 | F12: =C12*E12 -> 2230415 | H12: =RA!F77 -> 2037.4382 | I12: =RA!F86 -> 711.53846 | J12: =RA!F89 -> 268.8 | K12: =RA!F82 -> 550 | L12: =K12*0.05 -> 27.5 | M12: =SUM(H12:L12) -> 3595.2766 | N12: =M12*C12 -> 1362609.8 | O12: =F12-N12 -> 867805.16 | P12: =H12*C12 -> 772189.06 | Q12: =I12*C12 -> 269673.08 | R12: =J12*C12 -> 101875.2 | S12: =K12*C12 -> 208450 | T12: =L12*C12 -> 10422.5
A13: 6 | B13: Providing and placing in position of plain cement concrete M15 using 20 mm size hard blue granite broken stone jelly with M.Sand mixing with mixer machine including the cost of bailing/pumping wherever necessary laying the concrete in layers of not exceeding 15 cm thick, compacting, consolidation, vibratring,finishing, watering, curing etc. complete complying with Standard Specifications and as directed by the Departmental Engineers. | F13: =C13*E13 -> 0 | M13: =SUM(H13:L13) -> 0 | N13: =M13*C13 -> 0 | O13: =F13-N13 -> 0 | P13: =H13*C13 -> 0 | Q13: =I13*C13 -> 0 | R13: =J13*C13 -> 0 | S13: =K13*C13 -> 0 | T13: =L13*C13 -> 0
A14: 6.01 | B14: Below ground level upto 1.50 m | C14: 739 | D14: cum | E14: 6850 | F14: =C14*E14 -> 5062150 | H14: =RA!F101 -> 2287.4382 | I14: =RA!F110 -> 592.94872 | J14: =RA!F113 -> 224 | K14: =RA!F106 -> 550 | L14: =K14*0.05 -> 27.5 | M14: =SUM(H14:L14) -> 3681.8869 | N14: =M14*C14 -> 2720914.4 | O14: =F14-N14 -> 2341235.6 | P14: =H14*C14 -> 1690416.8 | Q14: =I14*C14 -> 438189.1 | R14: =J14*C14 -> 165536 | S14: =K14*C14 -> 406450 | T14: =L14*C14 -> 20322.5
A15: 6.02 | B15: Below ground level-Foundation upto 1.50 m to 4.50 m | C15: 220 | D15: cum | E15: 6984 | F15: =C15*E15 -> 1536480 | H15: =H14 -> 2287.4382 | I15: =I14 -> 592.94872 | J15: =J14 -> 224 | K15: =K14 -> 550 | L15: =K15*0.05 -> 27.5 | M15: =SUM(H15:L15) -> 3681.8869 | N15: =M15*C15 -> 810015.11 | O15: =F15-N15 -> 726464.89 | P15: =H15*C15 -> 503236.4 | Q15: =I15*C15 -> 130448.72 | R15: =J15*C15 -> 49280 | S15: =K15*C15 -> 121000 | T15: =L15*C15 -> 6050
A16: 7 | B16: Providing and placing in position of plain cement concrete M15 grade using 60% of 40mm size hard blue granite broken stone jelly and 40% of 20mm size hard blue granite broken stone jelly with M.Sand mixing with mixer machine including the cost of bailing/pumping wherever necessary laying the concrete in layers of not exceeding 15 cm thick, compacting, consolidation,vibrating,finishing, watering, curing etc. complete complying with Standard Specifications and as directed by the Departmental Engineers. | F16: =C16*E16 -> 0 | M16: =SUM(H16:L16) -> 0 | N16: =M16*C16 -> 0 | O16: =F16-N16 -> 0 | P16: =H16*C16 -> 0 | Q16: =I16*C16 -> 0 | R16: =J16*C16 -> 0 | S16: =K16*C16 -> 0 | T16: =L16*C16 -> 0
A17: 7.01 | B17: Below ground level up to 1.50 m | C17: 4986 | D17: cum | E17: 6510 | F17: =C17*E17 -> 32458860 | H17: =RA!F126 -> 2345.3887 | I17: =RA!F135 -> 711.53846 | J17: =RA!F138 -> 403.2 | K17: =RA!F131 -> 550 | L17: =K17*0.05 -> 27.5 | M17: =SUM(H17:L17) -> 4037.6272 | N17: =M17*C17 -> 20131609 | O17: =F17-N17 -> 12327251 | P17: =H17*C17 -> 11694108 | Q17: =I17*C17 -> 3547730.8 | R17: =J17*C17 -> 2010355.2 | S17: =K17*C17 -> 2742300 | T17: =L17*C17 -> 137115
A18: 7.02 | B18: Above ground level up to 4.50 m | C18: 1579 | D18: cum | E18: 6645 | F18: =C18*E18 -> 10492455 | H18: =H17 -> 2345.3887 | I18: =I17 -> 711.53846 | J18: =J17 -> 403.2 | K18: =K17 -> 550 | L18: =K18*0.05 -> 27.5 | M18: =SUM(H18:L18) -> 4037.6272 | N18: =M18*C18 -> 6375413.3 | O18: =F18-N18 -> 4117041.7 | P18: =H18*C18 -> 3703368.7 | Q18: =I18*C18 -> 1123519.2 | R18: =J18*C18 -> 636652.8 | S18: =K18*C18 -> 868450 | T18: =L18*C18 -> 43422.5
A19: 8 | B19: Supplying and fabrication and CC Block of size 1.50 X 1.50 X 0.90 m with Plain Cement Concrete 1:2:4 (one cement two m.sand and Four aggregate) using 40mm and down graded metal hard broken stone jelly for foundation including dewatering if found necessary and placing in position including ramming watering and curing etc. complete complying with Standard Specifications and as directed by the Departmental Engineers. | C19: 800 | D19: Nos | E19: 14577 | F19: =C19*E19 -> 11661600 | H19: =RA!F151 -> 4918.2465 | I19: =RA!F160 -> 351.37702 | J19: =RA!F163 -> 199.11111 | K19: =RA!F156 -> 1300 | L19: =K19*0.05 -> 65 | M19: =SUM(H19:L19) -> 6833.7346 | N19: =M19*C19 -> 5466987.7 | O19: =F19-N19 -> 6194612.3 | P19: =H19*C19 -> 3934597.2 | Q19: =I19*C19 -> 281101.61 | R19: =J19*C19 -> 159288.89 | S19: =K19*C19 -> 1040000 | T19: =L19*C19 -> 52000
A20: 9 | B20: Providing and laying in position standardised concrete Mix M-20 Grade in accordance with IS 456-2000 using 20mm and downgraded hard broken granite stone jelly for all RCC items of works with minium cement content of 325 kg/m3 and maxium water cement ratio of 0.55 including admixture (Plasticizer/Super plasticizer) in recommended proportions asper IS 9103 to accelerate, retard setting of concrete, improve workability without imparing strength and durability with about (5 cu.m) 7730 kg of 20 mm machine crushed stone jelly and with about (4.79 cu.m) 7670 kg of m.sand, but excluding cost of reinforcemnt grill and fabricating charges, centering and shuttering and also including and laying, vibrating with mechanical vibrators, finishing, curing etc. complete complying with Standard Specifications and as directed by the Departmental Engineers. | C20: 906 | D20: cum | E20: 8709 | F20: =C20*E20 -> 7890354 | H20: =RA!F176 -> 2665.9187 | I20: =RA!F184 -> 711.53846 | J20: =RA!F187 -> 336 | K20: =RA!F180 -> 350 | L20: =K20*0.05 -> 17.5 | M20: =SUM(H20:L20) -> 4080.9572 | N20: =M20*C20 -> 3697347.2 | O20: =F20-N20 -> 4193006.8 | P20: =H20*C20 -> 2415322.4 | Q20: =I20*C20 -> 644653.85 | R20: =J20*C20 -> 304416 | S20: =K20*C20 -> 317100 | T20: =L20*C20 -> 15855
A21: 10 | B21: Reinforced cement concrete M25 using 20mm hard broken stone jelly and downgreded to IS specified grading mixed in mixer machine including dewatering the placement site, laying the concrete in layers and in bays.vibrating compacting and finishing the surface with all lead and lifts, watering curing complete to attain the profile and strength as specified in the drawings and specification for various lengths and heights below and above ground level etc. complete complying with Standard Specifications and as directed by the Departmental Engineers. | C21: 32 | D21: cum | E21: 8857 | F21: =C21*E21 -> 283424 | H21: =RA!F200 -> 2770.9187 | I21: =RA!F208 -> 711.53846 | J21: =RA!F211 -> 336 | K21: =RA!F204 -> 350 | L21: =K21*0.05 -> 17.5 | M21: =SUM(H21:L21) -> 4185.9572 | N21: =M21*C21 -> 133950.63 | O21: =F21-N21 -> 149473.37 | P21: =H21*C21 -> 88669.399 | Q21: =I21*C21 -> 22769.231 | R21: =J21*C21 -> 10752 | S21: =K21*C21 -> 11200 | T21: =L21*C21 -> 560
A22: 11 | B22: Providing and placing plain cement concrete M20 grade using crusher broken hard granite course agrregate (well graded) of nominal maximum size of 20mm to specified grading to achieve the special characteristic strength of 20 N/mm2 in 28 days and mixing the ingredients in approved mixed placing in layers and vibrating water curing finishing the surface with all leads and lifts etc. complete in all respects so as to attain the profile strength specified in the approved drawing and specified in the approved drawing and specifications as per the direction of the engineer incharge of works and etc. complete complying with Standard Specifications and as directed by the Departmental Engineers. | F22: =C22*E22 -> 0 | M22: =SUM(H22:L22) -> 0 | N22: =M22*C22 -> 0 | O22: =F22-N22 -> 0 | P22: =H22*C22 -> 0 | Q22: =I22*C22 -> 0 | R22: =J22*C22 -> 0 | S22: =K22*C22 -> 0 | T22: =L22*C22 -> 0
A23: 11.01 | B23: Below ground level up to 1.50 m | C23: 225 | D23: cum | E23: 7280 | F23: =C23*E23 -> 1638000 | H23: =RA!F224 -> 2665.9187 | I23: =RA!F232 -> 711.53846 | J23: =RA!F235 -> 336 | K23: =RA!F228 -> 350 | L23: =K23*0.05 -> 17.5 | M23: =SUM(H23:L23) -> 4080.9572 | N23: =M23*C23 -> 918215.37 | O23: =F23-N23 -> 719784.63 | P23: =H23*C23 -> 599831.71 | Q23: =I23*C23 -> 160096.15 | R23: =J23*C23 -> 75600 | S23: =K23*C23 -> 78750 | T23: =L23*C23 -> 3937.5
A24: 11.02 | B24: Below ground level 1.50m to upto 4.50 m | C24: 525 | D24: cum | E24: 7414 | F24: =C24*E24 -> 3892350 | H24: =H23 -> 2665.9187 | I24: =I23 -> 711.53846 | J24: =J23 -> 336 | K24: =K23*1.1 -> 385 | L24: =K24*0.05 -> 19.25 | M24: =SUM(H24:L24) -> 4117.7072 | N24: =M24*C24 -> 2161796.3 | O24: =F24-N24 -> 1730553.7 | P24: =H24*C24 -> 1399607.3 | Q24: =I24*C24 -> 373557.69 | R24: =J24*C24 -> 176400 | S24: =K24*C24 -> 202125 | T24: =L24*C24 -> 10106.25
A25: 11.03 | B25: Above ground level upto 4.50m | C25: 2.9 | D25: cum | E25: 7416 | F25: =C25*E25 -> 21506.4 | H25: =H24 -> 2665.9187 | I25: =I24 -> 711.53846 | J25: =J24 -> 336 | K25: =K23*1.2 -> 420 | L25: =K25*0.05 -> 21 | M25: =SUM(H25:L25) -> 4154.4572 | N25: =M25*C25 -> 12047.926 | O25: =F25-N25 -> 9458.4742 | P25: =H25*C25 -> 7731.1643 | Q25: =I25*C25 -> 2063.4615 | R25: =J25*C25 -> 974.4 | S25: =K25*C25 -> 1218 | T25: =L25*C25 -> 60.9
A26: 12 | B26: Supplying fabricating and placing in position of Mild Steel (MS) or Ribbed Tor Steel (RTS) of grills for all R C C works including cost of steel, binding wire and labour charges for decoiling cutting, bending and tying the grills etc. complete complying with standard specifications and as directed by the Departmental Engineers. | C26: 1752 | D26: qtl. | E26: 9258 | F26: =C26*E26 -> 16220016 | H26: =RA!F244 -> 5376 | K26: =RA!F248 -> 1350 | L26: =K26*0.05 -> 67.5 | M26: =SUM(H26:L26) -> 6793.5 | N26: =M26*C26 -> 11902212 | O26: =F26-N26 -> 4317804 | P26: =H26*C26 -> 9418752 | Q26: =I26*C26 -> 0 | R26: =J26*C26 -> 0 | S26: =K26*C26 -> 2365200 | T26: =L26*C26 -> 118260
A27: 13 | B27: Supplying and filling in clean M- sand in layers of not more than 15cm thick well rammed watered and consolidated etc. complete complying with Standard Specifications and as directed by the Departmental Engineers. | C27: 398 | D27: cum | E27: 1785 | F27: =C27*E27 -> 710430 | H27: =RA!F255 -> 742.04947 | I27: =RA!F259 -> 202.93777 | J27: =RA!F262 -> 72.361809 | K27: =RA!F265 -> 200 | M27: =SUM(H27:L27) -> 1217.349 | N27: =M27*C27 -> 484504.92 | O27: =F27-N27 -> 225925.08 | P27: =H27*C27 -> 295335.69 | Q27: =I27*C27 -> 80769.231 | R27: =J27*C27 -> 28800 | S27: =K27*C27 -> 79600 | T27: =L27*C27 -> 0
A28: 14 | B28: Supplying and filling for inverted filter arrangements below CC blocks with 40 cm thick graded inverted filter provided in two or more layers (ie 20 mm, 40 mm, 63 mm.) size metal provided using HBGS jelly conveyance upto 100 m etc. complete complying with Standard Specifications and as directed by the Departmental Engineers. | C28: 795 | D28: cum | E28: 1580 | F28: =C28*E28 -> 1256100 | H28: =RA!F273 -> 1413.4276 | I28: =RA!F278 -> 232.22061 | J28: =RA!F281 -> 207.69811 | K28: =RA!F284 -> 200 | M28: =SUM(H28:L28) -> 2053.3463 | N28: =M28*C28 -> 1632410.3 | O28: =F28-N28 -> -376310.3 | P28: =H28*C28 -> 1123674.9 | Q28: =I28*C28 -> 184615.38 | R28: =J28*C28 -> 165120 | S28: =K28*C28 -> 159000 | T28: =L28*C28 -> 0
A29: 15 | B29: Supplying and Filling of Gravel in between the gap of CC Block with 75mm thick,etc. complete complying with Standard Specifications and as directed by the Departmental Engineers. | C29: 345 | D29: cum | E29: 447 | F29: =C29*E29 -> 154215 | H29: =RA!F293 -> 989.39929 | I29: =RA!F297 -> 75.250836 | J29: =RA!F300 -> 75.130435 | L29: =RA!F303 -> 60.869565 | M29: =SUM(H29:L29) -> 1200.6501 | N29: =M29*C29 -> 414224.29 | O29: =F29-N29 -> -260009.29 | P29: =H29*C29 -> 341342.76 | Q29: =I29*C29 -> 25961.538 | R29: =J29*C29 -> 25920 | S29: =K29*C29 -> 0 | T29: =L29*C29 -> 21000
A30: 16 | B30: Supplying and filling loose boulders of Size more than 300mm and weight more than 40kg in U/S and D/S apron using including conveyance,cost of materials etc. complete complying with standard specifications and as directed by the Departmental Engineers | C30: 4440 | D30: cum | E30: 2614 | F30: =C30*E30 -> 11606160 | H30: =RA!F311 -> 1611.3074 | I30: =RA!F315 -> 72.765073 | J30: =RA!F318 -> 99.891892 | L30: =RA!F321 -> 9.4594595 | M30: =SUM(H30:L30) -> 1793.4238 | N30: =M30*C30 -> 7962801.9 | O30: =F30-N30 -> 3643358.1 | P30: =H30*C30 -> 7154204.9 | Q30: =I30*C30 -> 323076.92 | R30: =J30*C30 -> 443520 | S30: =K30*C30 -> 0 | T30: =L30*C30 -> 42000
A31: 17 | B31: Rough stone dry packing using new stones for cone wrapping aprons and revetment including labour charges etc. complete complying with Standard Specifications and as directed by the Departmental Engineers. (.Cone Wrapping) | C31: 1099 | D31: cum | E31: 2315 | F31: =C31*E31 -> 2544185 | H31: =H30 -> 1611.3074 | I31: =I30 -> 72.765073 | J31: =J30 -> 99.891892 | L31: =L30 -> 9.4594595 | M31: =SUM(H31:L31) -> 1793.4238 | N31: =M31*C31 -> 1970972.8 | O31: =F31-N31 -> 573212.19 | P31: =H31*C31 -> 1770826.9 | Q31: =I31*C31 -> 79968.815 | R31: =J31*C31 -> 109781.19 | S31: =K31*C31 -> 0 | T31: =L31*C31 -> 10395.946
A32: 18 | B32: Jeddy stone packing using new stones u/s stone pitching including labour charges etc. complete complying with Standard Specifications and as directed by the Departmental Engineers. | C32: 450 | D32: cum | E32: 2614 | F32: =C32*E32 -> 1176300 | H32: =H31 -> 1611.3074 | I32: =I31 -> 72.765073 | J32: =J31 -> 99.891892 | L32: =L31 -> 9.4594595 | M32: =SUM(H32:L32) -> 1793.4238 | N32: =M32*C32 -> 807040.73 | O32: =F32-N32 -> 369259.27 | P32: =H32*C32 -> 725088.34 | Q32: =I32*C32 -> 32744.283 | R32: =J32*C32 -> 44951.351 | S32: =K32*C32 -> 0 | T32: =L32*C32 -> 4256.7568
A33: 19 | B33: Design, fabrication, supply, errection, testing and commissioning of fixed wheel type vertical lift gate(with top seal) consisting of skin plate, stiffeners, horizontal and vertical girders, wheels, guide rollers, rubber seals etc., with all accessories for canal escape/regulator vent including cost of materials, machinery, labour, cutting, aligning, welding, finishing, cleaning, applying one coat of zinc rich epoxy primer and three coats of cold applied coal tar epoxy paint,seal fixing etc., complete as per specifications and approved drawings with lead up to 1km and all lifts for structural steel components and all leads and all lifts including packing/forwarding charges for other materials. | C33: 4.44 | D33: tonne | E33: 233491 | F33: =C33*E33 -> 1036700 | K33: =E33*0.5 -> 116745.5 | M33: =SUM(H33:L33) -> 116745.5 | N33: =M33*C33 -> 518350.02 | O33: =F33-N33 -> 518350.02 | P33: =H33*C33 -> 0 | Q33: =I33*C33 -> 0 | R33: =J33*C33 -> 0 | S33: =K33*C33 -> 518350.02 | T33: =L33*C33 -> 0
A34: 20 | B34: Design, fabrication, supply, errection, testing and commissioning of supporting structure, platform, railing, ladder etc., with all accessories for operating canal escape/regulator gate including cost of all materials, machinery, labour, cutting, aligning, welding, finishing, cleaning, greasing, applying two coats of zinc chromate red oxide primer and three coats of approved synthetic enamel paint etc., complete as per specifications and approved drawings with lead up to 1km and all lifts for structural steel components and all leads and all lifts including packing/forwarding charges for other materials. | C34: 3.6 | D34: tonne | E34: 59143 | F34: =C34*E34 -> 212914.8 | K34: =E34*0.5 -> 29571.5 | M34: =SUM(H34:L34) -> 29571.5 | N34: =M34*C34 -> 106457.4 | O34: =F34-N34 -> 106457.4 | P34: =H34*C34 -> 0 | Q34: =I34*C34 -> 0 | R34: =J34*C34 -> 0 | S34: =K34*C34 -> 106457.4 | T34: =L34*C34 -> 0
A35: 21 | B35: Design, fabrication, supply, errection, testing and commissioning of embedded parts (with top seal) consisting of sill beam,wheel tracks,seal seats,guide rails,groove lining upto top etc., with all accessories for vertical lift roller gate for canal escape/regulator including cost of materials, machinery, labour, cutting, aligning, aligning, anchoring, welding, finishing, cleaning, applying one coat of zinc rich epoxy primer and four coats of cold applied coal tar epoxy paint,seal fixing etc., complete as per specifications and approved drawings with lead up to 1km and all lifts for structural steel components and all leads and all lifts including packing/forwarding charges for other materials. | C35: 6.6 | D35: tonne | E35: 243750 | F35: =C35*E35 -> 1608750 | K35: =E35*0.5 -> 121875 | M35: =SUM(H35:L35) -> 121875 | N35: =M35*C35 -> 804375 | O35: =F35-N35 -> 804375 | P35: =H35*C35 -> 0 | Q35: =I35*C35 -> 0 | R35: =J35*C35 -> 0 | S35: =K35*C35 -> 804375 | T35: =L35*C35 -> 0
A36: 22 | B36: Earth work in all soils except hard rock requiring blasting and conveying for formation of bund with lead of 0 to 100 metre with extra lead of 5 km deploying earth moving machinery and tippers including benching, formation of bunds, breaking clods, sectioning etc. complete complying with Standard Specifications and as directed by the Departmental Engineers. | C36: 60000 | D36: cum | E36: 336 | F36: =C36*E36 -> 20160000 | I36: =RA!F332 -> 99.230769 | J36: =RA!F335 -> 20.16 | L36: =RA!F338 -> 4.2 | M36: =SUM(H36:L36) -> 123.59077 | N36: =M36*C36 -> 7415446.2 | O36: =F36-N36 -> 12744554 | P36: =H36*C36 -> 0 | Q36: =I36*C36 -> 5953846.2 | R36: =J36*C36 -> 1209600 | S36: =K36*C36 -> 0 | T36: =L36*C36 -> 252000
A37: 23 | B37: Earthwork Excavation for foundation in all soils and sub soils and to full depth as may be directed except in hard rock requiring blasting inclusive of shoring, strutting and baling out of water wherever necessary refilling the sides of foundation with excavated sand on excavated soil other than sand in layer of 15 cm thick well rammed and consolidated depositing the surplus earth within the compound in places as shown by the departmental officers with initial lead and lift, clearing and leveling the site etc. complete complying with Standard Specifications and as directed by the Departmental Engineers. | C37: 5012 | D37: cum | E37: 106 | F37: =C37*E37 -> 531272 | I37: =RA!F348 -> 48.345509 | J37: =RA!F351 -> 40.223464 | L37: =RA!F354 -> 8.3798883 | M37: =SUM(H37:L37) -> 96.948861 | N37: =M37*C37 -> 485907.69 | O37: =F37-N37 -> 45364.308 | P37: =H37*C37 -> 0 | Q37: =I37*C37 -> 242307.69 | R37: =J37*C37 -> 201600 | S37: =K37*C37 -> 0 | T37: =L37*C37 -> 42000
A38: 24 | B38: Providing and making Gabion structure with Mechanically Woven Double Twisted Hexagonal shaped wire Mesh Gabion Boxes as per IS 16014:2012, Morth Clause 2500, of required size, Mesh Type 10x12 (D=100mm with tolerance of ± 2%) Zinc + PVC Coated, Mesh Wire diameter 2.7 / 3.7mm, mechanically edged / selvedged with partitions at every 1m interval and shall have minimum 10 numbers of openings per meter of mesh perpendicular to twist, tying with lacing wire of diameter 2.2 / 3.2mm (ID/OD), supplied @ 3% by weight of Gabion boxes, filled with boulders with least dimension of 200mm, as per drawing, all complete as per directions of Engineer-in-Charge. | C38: 10038 | D38: cum | E38: 3783 | F38: =C38*E38 -> 37973754 | H38: =RA!F363 -> 2927.0318 | I38: =RA!F367 -> 48.278082 | J38: =RA!F370 -> 66.276151 | K38: =RA!F373 -> 500 | M38: =SUM(H38:L38) -> 3541.586 | N38: =M38*C38 -> 35550441 | O38: =F38-N38 -> 2423313.4 | P38: =H38*C38 -> 29381545 | Q38: =I38*C38 -> 484615.38 | R38: =J38*C38 -> 665280 | S38: =K38*C38 -> 5019000 | T38: =L38*C38 -> 0
A39: 25 | B39: Providing and laying needle punched and mechanically bonded Non-woven Geotextiles of Type-I indigenously manufactured from high quality fibres on the prepared subgrade for separation as per MORTH Specification 702 | C39: 4950 | D39: sqm | E39: 161 | F39: =C39*E39 -> 796950 | H39: =RA!F381 -> 64.56 | K39: =RA!F384 -> 53.8 | M39: =SUM(H39:L39) -> 118.36 | N39: =M39*C39 -> 585882 | O39: =F39-N39 -> 211068 | P39: =H39*C39 -> 319572 | Q39: =I39*C39 -> 0 | R39: =J39*C39 -> 0 | S39: =K39*C39 -> 266310 | T39: =L39*C39 -> 0
A40: 26 | B40: Refilling with excavated soil (other than sand) complying with standard specification for filling in foundation and basement etc. complete complying with Standard Specifications and as directed by the Departmental Engineers. | C40: 4950 | D40: cum | E40: 44 | F40: =C40*E40 -> 217800 | I40: =RA!F393 -> 32.634033 | J40: =RA!F396 -> 34.909091 | L40: =RA!F399 -> 4.2424242 | M40: =SUM(H40:L40) -> 71.785548 | N40: =M40*C40 -> 355338.46 | O40: =F40-N40 -> -137538.46 | P40: =H40*C40 -> 0 | Q40: =I40*C40 -> 161538.46 | R40: =J40*C40 -> 172800 | S40: =K40*C40 -> 0 | T40: =L40*C40 -> 21000
...

Sheet RA
A1: WRO - Varanasi - Ariyalur
A2: Rate Analysis
A3: S.no | B3: Description | C3: Unit | D3: Qty | E3: Rate | F3: Amount
A4: 1 | B4: Clearing Scrub jungle
B5: Output for | C5: Sqm | D5: ='BOQ Major'!C4/17 -> 1520.5647
B6: Machineries
B7: Hire JCB - Day | C7: Day | D7: 1 | E7: 6500 | F7: =PRODUCT(D7:E7) -> 6500
B8: Hire Excavator | C8: Day | D8: 1 | E8: =140000/26 -> 5384.6154 | F8: =PRODUCT(D8:E8) -> 5384.6154 | M8: =40*250 -> 10000
F9: =SUM(F7:F8) -> 11884.615
F10: =F9/$D$5 -> 7.8159222
B11: Fuel
B12: Diesel | C12: Lit | D12: =+(D8*6*9) -> 54 | E12: 96 | F12: =PRODUCT(D12:E12) -> 5184
F13: =F12/D5 -> 3.4092597 | M13: Diesel | N13: =L179/2.5 -> 0 | O13: =N13*96 -> 0
B14: Man Power | M14: Driver | O14: 1000
B15: Helpers | C15: Nos | D15: 1 | E15: 700 | F15: =PRODUCT(D15:E15) -> 700 | M15: Tyre
F16: =F15/D5 -> 0.46035529
B18: Clearing Scrub jungle Total Per Sqm = | F18: =F10+F13+F16 -> 11.685537
A20: 2 | B20: Earthwork
B21: Output for | C21: Cum | D21: ='BOQ Split'!C5/60 -> 87.566667
B22: Machineries
B23: Hire Excavator | C23: Day | D23: 1 | E23: =140000/26 -> 5384.6154 | F23: =PRODUCT(D23:E23) -> 5384.6154
B24: Hire Excavator | C24: Day | D24: 1 | E24: =140000/26 -> 5384.6154 | F24: =PRODUCT(D24:E24) -> 5384.6154
F25: =SUM(F23:F24) -> 10769.231
F26: =F25/D21 -> 122.98322
B27: Fuel
B28: Diesel | C28: Lit | D28: =+(D24*6*8)*2 -> 96 | E28: 96 | F28: =PRODUCT(D28:E28) -> 9216
F29: =F28/D21 -> 105.24553
B30: Man Power
B31: Helpers | C31: Nos | D31: 2 | E31: 700 | F31: =PRODUCT(D31:E31) -> 1400
F32: =F31/D21 -> 15.987819
B34: Earthwork Total Per Cum = | F34: =F26+F29+F32 -> 244.21657
A36: 3 | B36: Earthwork
B37: Output for | C37: Cum | D37: ='BOQ Split'!C6/60 -> 489.68333
B38: Machineries
B39: Hire Excavator | C39: Day | D39: 1 | E39: =140000/26 -> 5384.6154 | F39: =PRODUCT(D39:E39) -> 5384.6154
B40: Hire Excavator | C40: Day | D40: 1 | E40: =140000/26 -> 5384.6154 | F40: =PRODUCT(D40:E40) -> 5384.6154
F41: =SUM(F39:F40) -> 10769.231
F42: =F41/D37 -> 21.992235
B43: Fuel
B44: Diesel | C44: Lit | D44: =+(D40*7*8)*2 -> 112 | E44: 96 | F44: =PRODUCT(D44:E44) -> 10752
...

Sheet IDC
B1: Period (months) | C1: 18
B2: Job value | C2: ='BOQ Split'!F43 -> 1.9847417e+08
A4: S.No | B4: DESCRIPTION | C4: Nos | D4: Months | E4: Value (Rs) | F4: Amount | G4: Amount Rs | H4: Rs in Lacs
A5: 1 | B5: Staff Salaries
B6: Designation / Role | C6: Nos | D6: Months | E6: Avg Salary | F6: Amount
B7: Project Engineer | C7: 1 | D7: 12 | E7: 60000 | F7: =PRODUCT(C7:E7) -> 720000
B8: Site Engineer | C8: 4 | D8: 12 | E8: 35000 | F8: =PRODUCT(C8:E8) -> 1680000
B9: Electrician | C9: 2 | D9: 18 | E9: =850*30 -> 25500 | F9: =PRODUCT(C9:E9) -> 918000
B10: TOTAL | C10: =SUM(C7:C9) -> 7 | D10: =SUMPRODUCT(C7:C9,D7:D9) -> 96 | G10: =SUM(F7:F9) -> 3318000 | H10: =+G10/100000 -> 33.18 | I10: =G10/$C$2 -> 0.016717541
A11: =A5+1 -> 2 | B11: Departmental Staff
B12: Dept | C12: 1 | D12: 12 | E12: 50000 | F12: =PRODUCT(C12:E12) -> 600000
B13: TOTAL | C13: =SUM(C12:C12) -> 1 | G13: =SUM(F12:F12) -> 600000 | H13: =+G13/10^5 -> 6 | I13: =G13/$C$2 -> 0.0030230634
A14: =A11+1 -> 3 | B14: PF / Pension / Super Annuation
B15: Bonus for Departmental workmen | C15: =C13 -> 1 | D15: 10 | E15: 10000 | F15: =+E15*C15*D15 -> 100000
B16: TOTAL | G16: =+SUM(F15:F15) -> 100000 | H16: =+G16/10^5 -> 1 | I16: =G16/$C$2 -> 0.0005038439
A17: =A14+1 -> 4 | B17: Welfare & Other Expenses
B18: Guest houses | C18: 1 | D18: 15 | E18: 7500 | F18: =+E18*D18*C18 -> 112500
B19: Furniture for Staff & GH | C19: 1 | D19: 1 | E19: 20000 | F19: =+C19*D19*E19 -> 20000
B20: Air conditioner | C20: 1 | D20: 1 | E20: 50000 | F20: =+C20*D20*E20 -> 50000
B21: Workmen travel Expenses | C21: 1 | D21: 4 | E21: 10000 | F21: 0
B22: GH Helpers | C22: 1 | D22: 12 | E22: 20000 | F22: =+C22*D22*E22 -> 240000
B23: Staff Mobile Expenses | C23: 1 | D23: 6 | E23: 700 | F23: =+C23*D23*E23 -> 4200
B24: Tea / Coffee - Staff | C24: 1 | D24: 12 | E24: 2000 | F24: =+C24*D24*E24 -> 24000
B25: Tea / Coffee - Clients | C25: 1 | D25: 12 | E25: 5000 | F25: =+C25*D25*E25 -> 60000
B26: Snacks / Water | C26: 1 | D26: 12 | E26: 5000 | F26: =+C26*D26*E26 -> 60000
B27: TOTAL | F27: =SUM(F17:F26) -> 570700 | G27: =+F27 -> 570700 | H27: =+G27/10^5 -> 5.707 | I27: =G27/$C$2 -> 0.0028754371
A28: =A17+1 -> 5 | B28: Safety PPEs
B29: Helmet, Shoe, Jacket, | C29: 12 | E29: 1000 | F29: =+E29*C29 -> 12000
B30: TOTAL | F30: =+SUM(F29:F29) -> 12000 | G30: =+F30 -> 12000 | H30: =+G30/10^5 -> 0.12 | I30: =G30/$C$2 -> 6.0461268e-05
A31: =A28+1 -> 6 | B31: Water & Sewage & Power & Fuel
B32: Curing Tank | C32: 1 | D32: 1 | E32: 60000 | F32: =+E32*D32*C32 -> 60000
B33: Sintex for Labour water & office | C33: 1 | D33: 1 | E33: 10000 | F33: =+E33*D33*C33 -> 10000
B34: lights fixtures | C34: 1 | D34: 10 | E34: 1500 | F34: =+E34*D34*C34 -> 15000
B35: cable | C35: 0 | E35: 0.6 | F35: =E35*F34 -> 9000
B36: wire for lighting | C36: 0 | E36: 0.6 | F36: =F35 -> 9000
B37: Power Accessories & Maintenance | C37: 0 | D37: 1 | E37: 1 | F37: 10000
