Workbook
Name \0: #REF!
Name \0: #REF!
Name \a: #N/A
Name \b: #N/A
Name \C: #REF!
Name \C: #REF!
Name \c1: #REF!
Name \c1: #REF!
Name \c2: #REF!
Name \c2: #REF!
Name \D: #REF!
Name \D: #REF!
Name \l: #REF!
Name \l: #REF!
Name \M: #REF!
Name \M: #REF!
Name \N: #REF!
Name \N: #REF!
Name \p: #REF!
Name \p: #REF!
Name \R: #REF!
Name \R: #REF!
Name \S: #REF!
Name \S: #REF!
Name \U: #REF!
Name \U: #REF!
Name \V: #REF!
Name \V: #REF!
Name \x: #REF!
Name \x: #REF!
Name _: "tcap"
Name _\wdr: #REF!
Name _\wdr: #REF!
Name __________________________________aaa5: #REF!
Name __________________________________aaa5: #REF!
Name __________________________________D199617: #REF!
Name _________________________________aaa5: #REF!
Name _________________________________aaa5: #REF!
Name _________________________________D199617: #REF!
Name ________________________________aaa5: #REF!
Name ________________________________aaa5: #REF!
Name ________________________________D199617: #REF!
Name _______________________________aaa5: #REF!
Name _______________________________aaa5: #REF!
Name _______________________________D199617: #REF!
Name ______________________________aaa5: #REF!
Name ______________________________aaa5: #REF!
Name ______________________________D199617: #REF!
Name _____________________________aaa5: #REF!
Name _____________________________aaa5: #REF!
Name _____________________________D199617: #REF!
Name _____________________________SS2: #REF!
Name _____________________________SS2: #REF!
Name ____________________________aaa5: #REF!
Name ____________________________aaa5: #REF!
Name ____________________________D199617: #REF!
Name ___________________________D199617: #REF!
Name __________________________D199617: #REF!
Name __________________________ind1: #REF!
Name __________________________ind1: #REF!

Sheet Pandalur -covering
A12: R.DINESH KUMAR ASS.ENGINEER
B13: RC NO:- 1/AE/Nilgiris/Pandalur/BILL Dt:
A14: TO,
A15: EXE.ENGINEER
A16: TNCSC
A17: GOPALAPURAM
A18: CHENNAI
A19: Sir,
A20: Sub: | B20: TNCSC –Coimbatore Sub Division - Nilgiris Region – Construction of New Taluk operational godown of 2500M.T (1X1500MT, 1X1000MT) capacity in TNCSC campus at Survey No.2347/1 to an extent of 1.21.44 Hectare at Nelliyalam Village in Pandalur Taluk in Nilgiris District. - L.S II & Part Bill – Submitted Reg
A22: Ref: LS / Agt.No. 362 /2023-24
A24: I submit here with the L.S I & Part Bill for the following work for favour of taking further necessary action please. | N24: =UPPER(B27) -> CONSTRUCTION OF NEW TALUK OPERATIONAL GODOWN OF 2500M.T (1X1500MT, 1X1000MT) CAPACITY IN TNCSC CAMPUS AT SURVEY NO.2347/1 TO AN EXTENT OF 1.21.44 HECTARE AT NELLIYALAM VILLAGE IN PANDALUR TALUK IN NILGIRIS DISTRICT.
A26: S.No | B26: Name of work
A27: 1 | B27: Construction of New Taluk operational godown of 2500M.T (1X1500MT, 1X1000MT) capacity in TNCSC campus at Survey No.2347/1 to an extent of 1.21.44 Hectare at Nelliyalam Village in Pandalur Taluk in Nilgiris District.
D29: Thanking you
A31: Encl: Bill form with M.Book | G31: Yours Faithfully
A32: 6981ACE, 6979ACE, 58266CE | F32: For Tamil Nadu Civil Supply Corporation
F35: Asst.Engineer
G36: TNCSC Coimbatore
A37: Kindly forwarding the bill for payment to Executive Engineer / Chennai
A38: Counter Signed
A41: JR/Senior Regional Manager
A42: TNCSC Nilgiris

Sheet BOQ
A1: Construction of New Taluk operational godown of 2500M.T capacity in TNCSC campus at Survey No.2347/1 to an extent of 1.21.44 Hectare at Nelliyalam Village in Pandalur Taluk in Nilgiris District.
A2: BOQ
A3: S.No | B3: Item Description | C3: Quantity | D3: Units | E3: Rate | F3: Amount
A4: 1.01 | B4: Clearing Scrub Jungle as directed by the departmental officers. | C4: 4000 | D4: M2 | E4: 7.55 | F4: =E4*C4 -> 30200
A5: 1.02 | B5: EARTH WORK excavation for foundation in all classes of soils and subsoils to full depth, as may be directed except in hard rock, requiring blasting including initial leads and lifts and refilling the sides of foundation with excavated earth in 150mm layers well watered rammed and consolidated including depositing surplus earth with in the Godown or inside compound in places shown with initial leads and lifts, clearing, leveling site, shoring, strutting, baling of water wherever necessary etc., complete complying with standard specification and as directed. | C5: 447 | D5: M3 | E5: 279.85 | F5: =E5*C5 -> 125092.95
A6: 1.03 | B6: Refilling with excavated earth in basement including watering, rammed and consolidated etc., complete complying with standard specifications and as directed. | C6: 273 | D6: M3 | E6: 54.55 | F6: =E6*C6 -> 14892.15
A7: 1.04 | B7: Supplying and filling in foundation with Gravel in layers of not exceeding 150mm thick well watered, rammed and consolidated including watering etc., complete complying with standard specification and as directed. | C7: 450 | D7: M3 | E7: 2347 | F7: =E7*C7 -> 1056150
A8: 1.05 | B8: Refilling with conveyed earth to a lead of 10KM for filling in foundation and basement including watering, rammed and consolidated etc., complete and as directed by the departmental officers. | C8: 824 | D8: M3 | E8: 278.3 | F8: =E8*C8 -> 229319.2
A9: 1.06 | B9: Supplying and filling in basement with wetmix 250mm thick in layers of not exceeding 250mm thick, well watered, rammed and consolidated including machineries for hire and running charges leader 5 Cum capacity, hire charges for tipper, water sprinkler,` vibratory roller all labour charges etc., complete complying with standard specification and as directed | C9: 300 | D9: M3 | E9: 4269.95 | F9: =E9*C9 -> 1280985
A10: 1.07 | B10: CEMENT CONCRETE 1:5:10(one cement , five sand and ten aggregate)using 40mm gauge hard broken granite stone jelly for foundation including de-watering side shuttering , strutting, wherever necessary including curing etc., complete complying with standard specifications and as directed. | C10: 270 | D10: M3 | E10: 8093 | F10: =E10*C10 -> 2185110
A11: 1.08 | B11: BRICK WORK in cement mortar 1:5(One cement ,Five sand)using best quality Country Bricks of size 8 ¾”x4 ¼” x2¼’’ for walls including cost of scaffolding curing ,finishing etc., complete complying with standard specifications and as directed. In foundation and basement. | C11: 141 | D11: M3 | E11: 7536.75 | F11: =E11*C11 -> 1062681.8
A12: 1.09 | B12: In ground floor Upto 4.50M height above basement. | C12: 243 | D12: M3 | E12: 7647.2 | F12: =E12*C12 -> 1858269.6
A13: 1.1 | B13: Above 4.50M height above basement. | C13: 103 | D13: M3 | E13: 7870.19 | F13: =E13*C13 -> 810629.57
A14: 1.11 | B14: Providing FORM WORK for centering the soffits of all reinforcement concrete work including strutting to the required (3 metre) height with mild-steel sheets of size 90cmx60cm 10 gauge stiffened with welded mild steel angles of size 25mmx25mmx3mm laid with country wood joist of average of size 10cmx6.50cm at about 90cm centres with casurina props of 13cm dia at 75cm centre to centre with all nails coir,wedges complete and removing the form work after necessary curing period as directed by the corporations officers. The rates should inclusives of cutting , bending, welding , charges of M.S sheets, M.S. angles etc., Complete Column footing, Plinth beam, top tie beame | C14: 715 | D14: M2 | E14: 1159.9 | F14: =E14*C14 -> 829328.5
A15: 1.12 | B15: Rectangular beams and floor slabs, tie beams, lintels, landing slab, loft etc., | C15: 805 | D15: M2 | E15: 1278.8 | F15: =E15*C15 -> 1029434
... A58: 1.55 | B58: Supplying and fixing AC ventilating shaft of 110mm dia with 3 metre height including cost of of 110mm dia AC cylindrical cowl of best approved quality etc., complete complying with standard specification and as directed by the departmental officers. | C58: 3.5 | D58: RM | E58: 859.7 | F58: =E58*C58 -> 3008.95
B59: Sub Total = | F59: =SUM(F4:F58) -> 35729965
B60: GST 18% = | F60: =F59*0.18 -> 6431393.6
B61: Grand Total = | F61: =F59+F60 -> 42161358
B64: Basic | F64: 42169769
B65: Diff | F65: =F61-F64 -> -8411.0404
B66: % | F66: =F65/F61 -> -0.00019949643

Sheet Comparative
A1: COMPARATIVE STATEMENT
A2: Name of Work :Construction of New Taluk operational godown of 2500M.T(1X1500MT, 1X1000MT) capacity in TNCSC campus at Survey No.2347/1 to an extent of 1.21.44 Hectare at Nelliyalam Village in Pandalur Taluk in Nilgiris District.
B3: 450 | E3: 3622324 | H3: 1752324
A4: S. No | B4: Description of work | C4: Agreement Rate | D4: per | E4: As per Agreement | G4: As per Execution | I4: Excess | L4: Balance
E5: Qty | F5: Amount | G5: Qty | H5: Amount | I5: Qty | J5: % | K5: Amount | L5: Qty | M5: % | N5: Amount
A6: 1.01 | B6: Clearing Scrub Jungle as directed by the departmental officers. | C6: 7.55 | D6: M2 | E6: 4000 | F6: =C6*E6 -> 30200 | G6: ='Bill Abs'!C8 -> 4000 | H6: =G6*C6 -> 30200 | I6: =IF(E6<G6,G6-E6,) -> 0 | J6: =I6/E6 -> 0 | K6: =I6*C6 -> 0 | L6: =IF(E6>G6,E6-G6,) -> 0 | M6: =L6/E6 -> 0 | N6: =L6*C6 -> 0
A7: 1.02 | B7: EARTH WORK excavation for foundation in all classes of soils and subsoils to full depth, as may be directed except in hard rock, requiring blasting including initial leads and lifts and refilling the sides of foundation with excavated earth in 150mm layers well watered rammed and consolidated including depositing surplus earth with in the Godown or inside compound in places shown with initial leads and lifts, clearing, leveling site, shoring, strutting, baling of water wherever necessary etc., complete complying with standard specification and as directed. | C7: 279.85 | D7: M3 | E7: 447 | F7: =C7*E7 -> 125092.95 | G7: ='Bill Abs'!C9 -> 566.32 | H7: =G7*C7 -> 158484.65 | I7: =IF(E7<G7,G7-E7,) -> 119.32 | J7: =I7/E7 -> 0.26693512 | K7: =I7*C7 -> 33391.702 | L7: =IF(E7>G7,E7-G7,) -> 0 | M7: =L7/E7 -> 0 | N7: =L7*C7 -> 0
A8: 1.03 | B8: Refilling with excavated earth in basement including watering, rammed and consolidated etc., complete complying with standard specifications and as directed. | C8: 54.55 | D8: M3 | E8: 273 | F8: =C8*E8 -> 14892.15 | G8: ='Bill Abs'!C10 -> 269.33 | H8: =G8*C8 -> 14691.951 | I8: =IF(E8<G8,G8-E8,) -> 0 | J8: =I8/E8 -> 0 | K8: =I8*C8 -> 0 | L8: =IF(E8>G8,E8-G8,) -> 3.67 | M8: =L8/E8 -> 0.013443223 | N8: =L8*C8 -> 200.1985
A9: 1.04 | B9: Supplying and filling in foundation with Gravel in layers of not exceeding 150mm thick well watered, rammed and consolidated including watering etc., complete complying with standard specification and as directed. | C9: 2347 | D9: M3 | E9: 450 | F9: =C9*E9 -> 1056150 | G9: ='Bill Abs'!C11 -> 927.68 | H9: =G9*C9 -> 2177265 | I9: =IF(E9<G9,G9-E9,) -> 477.68 | J9: =I9/E9 -> 1.0615111 | K9: =I9*C9 -> 1121115 | L9: =IF(E9>G9,E9-G9,) -> 0 | M9: =L9/E9 -> 0 | N9: =L9*C9 -> 0
A10: 1.05 | B10: Refilling with conveyed earth to a lead of 10KM for filling in foundation and basement including watering, rammed and consolidated etc., complete and as directed by the departmental officers. | C10: 278.3 | D10: M3 | E10: 824 | F10: =C10*E10 -> 229319.2 | G10: ='Bill Abs'!C12 -> 822.94 | H10: =G10*C10 -> 229024.2 | I10: =IF(E10<G10,G10-E10,) -> 0 | J10: =I10/E10 -> 0 | K10: =I10*C10 -> 0 | L10: =IF(E10>G10,E10-G10,) -> 1.06 | M10: =L10/E10 -> 0.0012864078 | N10: =L10*C10 -> 294.998
A11: 1.06 | B11: Supplying and filling in basement with wetmix 250mm thick in layers of not exceeding 250mm thick, well watered, rammed and consolidated including machineries for hire and running charges leader 5 Cum capacity, hire charges for tipper, water sprinkler,` vibratory roller all labour charges etc., complete complying with standard specification and as directed | C11: 4269.95 | D11: M3 | E11: 300 | F11: =C11*E11 -> 1280985 | G11: ='Bill Abs'!C13 -> 209.48 | H11: =G11*C11 -> 894469.13 | I11: =IF(E11<G11,G11-E11,) -> 0 | J11: =I11/E11 -> 0 | K11: =I11*C11 -> 0 | L11: =IF(E11>G11,E11-G11,) -> 90.52 | M11: =L11/E11 -> 0.30173333 | N11: =L11*C11 -> 386515.87
A12: 1.07 | B12: CEMENT CONCRETE 1:5:10(one cement , five sand and ten aggregate)using 40mm gauge hard broken granite stone jelly for foundation including de-watering side shuttering , strutting, wherever necessary including curing etc., complete complying with standard specifications and as directed. | C12: 8093 | D12: M3 | E12: 270 | F12: =C12*E12 -> 2185110 | G12: ='Bill Abs'!C14 -> 173.76 | H12: =G12*C12 -> 1406239.7 | I12: =IF(E12<G12,G12-E12,) -> 0 | J12: =I12/E12 -> 0 | K12: =I12*C12 -> 0 | L12: =IF(E12>G12,E12-G12,) -> 96.24 | M12: =L12/E12 -> 0.35644444 | N12: =L12*C12 -> 778870.32
A13: 1.08 | B13: BRICK WORK in cement mortar 1:5(One cement ,Five sand)using best quality Country Bricks of size 8 ¾”x4 ¼” x2¼’’ for walls including cost of scaffolding curing ,finishing etc., complete complying with standard specifications and as directed. In foundation and basement. | C13: 7536.75 | D13: M3 | E13: 141 | F13: =C13*E13 -> 1062681.8 | G13: ='Bill Abs'!C15 -> 181.41 | H13: =G13*C13 -> 1367241.8 | I13: =IF(E13<G13,G13-E13,) -> 40.41 | J13: =I13/E13 -> 0.28659574 | K13: =I13*C13 -> 304560.07 | L13: =IF(E13>G13,E13-G13,) -> 0 | M13: =L13/E13 -> 0 | N13: =L13*C13 -> 0
A14: 1.09 | B14: In ground floor Upto 4.50M height above basement. | C14: 7647.2 | D14: M3 | E14: 243 | F14: =C14*E14 -> 1858269.6 | G14: ='Bill Abs'!C16 -> 247.35 | H14: =G14*C14 -> 1891534.9 | I14: =IF(E14<G14,G14-E14,) -> 4.35 | J14: =I14/E14 -> 0.017901235 | K14: =I14*C14 -> 33265.32 | L14: =IF(E14>G14,E14-G14,) -> 0 | M14: =L14/E14 -> 0 | N14: =L14*C14 -> 0
A15: 1.1 | B15: Above 4.50M height above basement. | C15: 7870.19 | D15: M3 | E15: 103 | F15: =C15*E15 -> 810629.57 | G15: ='Bill Abs'!C17 -> 81.18 | H15: =G15*C15 -> 638902.02 | I15: =IF(E15<G15,G15-E15,) -> 0 | J15: =I15/E15 -> 0 | K15: =I15*C15 -> 0 | L15: =IF(E15>G15,E15-G15,) -> 21.82 | M15: =L15/E15 -> 0.21184466 | N15: =L15*C15 -> 171727.55
A16: 1.11 | B16: Providing FORM WORK for centering the soffits of all reinforcement concrete work including strutting to the required (3 metre) height with mild-steel sheets of size 90cmx60cm 10 gauge stiffened with welded mild steel angles of size 25mmx25mmx3mm laid with country wood joist of average of size 10cmx6.50cm at about 90cm centres with casurina props of 13cm dia at 75cm centre to centre with all nails coir,wedges complete and removing the form work after necessary curing period as directed by the corporations officers. The rates should inclusives of cutting , bending, welding , charges of M.S sheets, M.S. angles etc., Complete Column footing, Plinth beam, top tie beame | C16: 1159.9 | D16: M2 | E16: 715 | F16: =C16*E16 -> 829328.5 | G16: ='Bill Abs'!C18 -> 743.97 | H16: =G16*C16 -> 862930.8 | I16: =IF(E16<G16,G16-E16,) -> 28.97 | J16: =I16/E16 -> 0.040517483 | K16: =I16*C16 -> 33602.303 | L16: =IF(E16>G16,E16-G16,) -> 0 | M16: =L16/E16 -> 0 | N16: =L16*C16 -> 0
A17: 1.12 | B17: Rectangular beams and floor slabs, tie beams, lintels, landing slab, loft etc., | C17: 1278.8 | D17: M2 | E17: 805 | F17: =C17*E17 -> 1029434 | G17: ='Bill Abs'!C19 -> 661.02 | H17: =G17*C17 -> 845312.38 | I17: =IF(E17<G17,G17-E17,) -> 0 | J17: =I17/E17 -> 0 | K17: =I17*C17 -> 0 | L17: =IF(E17>G17,E17-G17,) -> 143.98 | M17: =L17/E17 -> 0.17885714 | N17: =L17*C17 -> 184121.62 | Q17: =487*0.25 -> 121.75
A18: 1.13 | B18: Column, ratguard slab, curtain slab and sun shades etc., | C18: 1406.65 | D18: M2 | E18: 906 | F18: =C18*E18 -> 1274424.9 | G18: ='Bill Abs'!C20 -> 953.6 | H18: =G18*C18 -> 1341381.4 | I18: =IF(E18<G18,G18-E18,) -> 47.6 | J18: =I18/E18 -> 0.052538631 | K18: =I18*C18 -> 66956.54 | L18: =IF(E18>G18,E18-G18,) -> 0 | M18: =L18/E18 -> 0 | N18: =L18*C18 -> 0
A19: 1.14 | B19: Supplying, fabricating and placing in position MS/RTS grills for reinforcement for all R.C.C.works including cost of steel, labour for straightening, bending, cranking, tying grills with 18 gauge galvanized binding wire and placing grills in position complete complying with standard specification and as directed.. | C19: 10099.75 | D19: QTL | E19: 524.6 | F19: =C19*E19 -> 5298328.9 | G19: ='Bill Abs'!C21 -> 388.26122 | H19: =G19*C19 -> 3921341.3 | I19: =IF(E19<G19,G19-E19,) -> 0 | J19: =I19/E19 -> 0 | K19: =I19*C19 -> 0 | L19: =IF(E19>G19,E19-G19,) -> 136.33878 | M19: =L19/E19 -> 0.25989092 | N19: =L19*C19 -> 1376987.6
A20: 1.15 | B20: Supplying and fixing (under lintel grove) cold rolled ROLLING SHUTTERS of approved quality of 18 gauge 7.5 cm wide cold rolled lathe section in one piece interlocked together with specially designed pipe shaft with adequate number of high tensile steels wire springs of approved quality complete with brackets side guides and arrangements for inside and outside locking arrangements with push and pull operations and pulling back handle with all accessories without workmanship and the entire shutter painted with two coats of best quality anti-corrosive nut brown color paint over one coat of red oxide primer and clear opening of 1.8 M width 2.60 M | C20: 14635 | D20: NOS | E20: 10 | F20: =C20*E20 -> 146350 | G20: ='Bill Abs'!C22 -> 12 | H20: =G20*C20 -> 175620 | I20: =IF(E20<G20,G20-E20,) -> 2 | J20: =I20/E20 -> 0.2 | K20: =I20*C20 -> 29270 | L20: =IF(E20>G20,E20-G20,) -> 0 | M20: =L20/E20 -> 0 | N20: =L20*C20 -> 0
A21: 1.16 | B21: Supplying and fixing of Steel glazed AIR INLET WINDOWs of size 0.6m x 0.6m using extruded angles (Z-section) alround for frame with centre mullion (T-section) and shutter with the same Z-section properly fixed with hinges 2 nos. for each shutter. The panel of shutter fixed with G.I. sheet of'18 gauge and necessary locking arrangements including weld mesh cover using weld mesh 25mm x 25mm x 10mm gauge and welded with iron square bars of 10mm size - 3nos. horizontally and 2nos. vertically welded together to form a grill and welding grill to the main frame with 4mm thick and 12mm wide MS flats. The rate is also inclusive of one coat of steel primer and two coats of ANTI CORROSIVE METALLIC paint and quality, 2 nos. | C21: 3453.2 | D21: NOS | E21: 36 | F21: =C21*E21 -> 124315.2 | G21: ='Bill Abs'!C23 -> 34 | H21: =G21*C21 -> 117408.8 | I21: =IF(E21<G21,G21-E21,) -> 0 | J21: =I21/E21 -> 0 | K21: =I21*C21 -> 0 | L21: =IF(E21>G21,E21-G21,) -> 2 | M21: =L21/E21 -> 0.055555556 | N21: =L21*C21 -> 6906.4
A22: 1.17 | B22: Supplying and fixing steel N-Type VENTILATOR of size 2.60m x 0.60m using extruded angle (Z-section 25mmx25mmx3mm) for outer frames with center mullion (T-section)and with weld mesh of 25mmx25mm 10guage on all three sides ( 2 verticals 1 horizontal) and 10mm size MS square bars horizontally one at top and one at bottom welded to the frames with necessary MS flats of size 20mmx4mm thick | C22: 4250 | D22: NOS | E22: 92 | F22: =C22*E22 -> 391000 | G22: ='Bill Abs'!C24 -> 92 | H22: =G22*C22 -> 391000 | I22: =IF(E22<G22,G22-E22,) -> 0 | J22: =I22/E22 -> 0 | K22: =I22*C22 -> 0 | L22: =IF(E22>G22,E22-G22,) -> 0 | M22: =L22/E22 -> 0 | N22: =L22*C22 -> 0
A23: 1.18 | B23: Providing vacuum de watered controlled cement surfacing 100mm thick in required slope and chamber confirming M20 grade with 20mm size stone aggregate cast in situ ,smooth finish and leveling with double framed screed vibrator ,excess water to be removed through vacuum pump with bottom and top filter mat duly sealing the edges all round including provisions of polythene sheet below the concrete layer before placing of concrete and finishing with paver floated and power trawler to obtain the hard surface including provision of expansion joints at 6mtr intervals across the platform by cutting 6mm wide and full depth of concrete by contractors | C23: 1653.4 | D23: M2 | E23: 1503 | F23: =C23*E23 -> 2485060.2 | G23: ='Bill Abs'!C25 -> 0 | H23: =G23*C23 -> 0 | I23: =IF(E23<G23,G23-E23,) -> 0 | J23: =I23/E23 -> 0 | K23: =I23*C23 -> 0 | L23: =IF(E23>G23,E23-G23,) -> 1503 | M23: =L23/E23 -> 1 | N23: =L23*C23 -> 2485060.2
A24: 1.19 | B24: PLASTERING with cement mortor 1:5 (one cement and five sand) 12mm thick including cost of scaffolding, finishing, curing etc., complete complying with standard specification and as directed. | C24: 356.05 | D24: M2 | E24: 3522 | F24: =C24*E24 -> 1254008.1 | G24: ='Bill Abs'!C26 -> 1480.4 | H24: =G24*C24 -> 527096.42 | I24: =IF(E24<G24,G24-E24,) -> 0 | J24: =I24/E24 -> 0 | K24: =I24*C24 -> 0 | L24: =IF(E24>G24,E24-G24,) -> 2041.6 | M24: =L24/E24 -> 0.57967064 | N24: =L24*C24 -> 726911.68
A25: 1.2 | B25: PLASTERING with the exposed RCC surface with C.M.1:3(one cement and three sand) 10mm thick including cost of scaffolding, finishing, curing etc., complete complying with standard Specification and as directed. | C25: 401.1 | D25: M2 | E25: 1350 | F25: =C25*E25 -> 541485 | G25: ='Bill Abs'!C27 -> 539.81 | H25: =G25*C25 -> 216517.79 | I25: =IF(E25<G25,G25-E25,) -> 0 | J25: =I25/E25 -> 0 | K25: =I25*C25 -> 0 | L25: =IF(E25>G25,E25-G25,) -> 810.19 | M25: =L25/E25 -> 0.60014074 | N25: =L25*C25 -> 324967.21
A26: 1.21 | B26: Painting the walls with two coats of exterior emulsion paint of first class approved quality and colour over a priming coat including thorough scrapping, clean removal of dirt, and including necessary plaster of paris putty, wherever required etc., complete complying with standard specification and as directed. | C26: 309.2 | D26: M2 | E26: 3209 | F26: =C26*E26 -> 992222.8 | G26: ='Bill Abs'!C28 -> 0 | H26: =G26*C26 -> 0 | I26: =IF(E26<G26,G26-E26,) -> 0 | J26: =I26/E26 -> 0 | K26: =I26*C26 -> 0 | L26: =IF(E26>G26,E26-G26,) -> 3209 | M26: =L26/E26 -> 1 | N26: =L26*C26 -> 992222.8
A27: 1.22 | B27: Supplying, fabricating and fixing in position M.S.Channel 100x50x6mm at the edge of loading platform with M.S bolt of 16mm at the edge of loading platform with M.S bolt of 16mm at the edge of loading platform finishing in flush with the slab with C.M 1:3 complete including painting the exposed surface of MS channel with two coats of ANI Corrosive metalic net brown colour paint over one coat red oxide primer etc., complete. | C27: 1277 | D27: RM | E27: 76.4 | F27: =C27*E27 -> 97562.8 | G27: ='Bill Abs'!C29 -> 81.5 | H27: =G27*C27 -> 104075.5 | I27: =IF(E27<G27,G27-E27,) -> 5.1 | J27: =I27/E27 -> 0.066753927 | K27: =I27*C27 -> 6512.7 | L27: =IF(E27>G27,E27-G27,) -> 0 | M27: =L27/E27 -> 0 | N27: =L27*C27 -> 0
A28: 1.23 | B28: Supplying and fixing of Rotary Ventilators over the roof with necessary bolt and nut arrangement to withstand the wind velocity as specified by the departmental officers. (Size 600mm x 600mm) | C28: 18000 | D28: NOS | E28: 11 | F28: =C28*E28 -> 198000 | G28: ='Bill Abs'!C30 -> 0 | H28: =G28*C28 -> 0 | I28: =IF(E28<G28,G28-E28,) -> 0 | J28: =I28/E28 -> 0 | K28: =I28*C28 -> 0 | L28: =IF(E28>G28,E28-G28,) -> 11 | M28: =L28/E28 -> 1 | N28: =L28*C28 -> 198000
A29: 1.24 | B29: Supplying and laying of profiled colour galvalume sheet with combination 55A1:43 4Zn:1:6SI of TCT bent type 0.47mm thick and standard width of 1.06m with yield strength of 550 MPA made from high tensile/ CR sheets of approved quality for roofing with necessary fixing arrangements like 65m abd long hexagonal head screws with EPDM rubber seal etc., complete complying with standard specification and as directed by the departmental officer. (Test certificate for quality should be furnished on receipt of material at site) | C29: =1198.15 -> 1198.15 | D29: M2 | E29: 1911 | F29: =C29*E29 -> 2289664.7 | G29: ='Bill Abs'!C31 -> 1897.96 | H29: =G29*C29*0.7 -> 1591828.5 | I29: =IF(E29<G29,G29-E29,) -> 0 | J29: =I29/E29 -> 0 | K29: =I29*C29 -> 0 | L29: =IF(E29>G29,E29-G29,) -> 13.04 | M29: =L29/E29 -> 0.0068236525 | N29: =L29*C29 -> 15623.876
A30: 1.25 | B30: Supplying and roofing with Galvalume sheet ridge pieces of size 1.00M x 0.7M, 0.47mm thick with necessary U or J bolt and nuts G.I washers etc., complete For the above works skilled man power, necessary tools, equipments, power supply, water supply including transport, any other statuary approval required for the transporting the materials shall be duly obtained by the contractor. (Test certificate for quality should be furnished on receipt of material at site) | C30: =656.5 -> 656.5 | D30: RM | E30: 107 | F30: =C30*E30 -> 70245.5 | G30: ='Bill Abs'!C32 -> 105.92 | H30: =G30*C30*0.7 -> 48675.536 | I30: =IF(E30<G30,G30-E30,) -> 0 | J30: =I30/E30 -> 0 | K30: =I30*C30 -> 0 | L30: =IF(E30>G30,E30-G30,) -> 1.08 | M30: =L30/E30 -> 0.010093458 | N30: =L30*C30 -> 709.02
A31: 1.26 | B31: Supplying and fixing corrugated Poly Carbonate sheet of size 3mx1.06m of 3mm thick on the roof in-between the colour coated Galvalume sheets for proper lighting with necessary G.I screws and EPDM rubber washers, Complying with standard specification and as direct and specified by the departmental officers including cost of loading unloading and transportion charges etc., complete. | C31: 1427.85 | D31: M2 | E31: 34 | F31: =C31*E31 -> 48546.9 | G31: ='Bill Abs'!C33 -> 0 | H31: =G31*C31 -> 0 | I31: =IF(E31<G31,G31-E31,) -> 0 | J31: =I31/E31 -> 0 | K31: =I31*C31 -> 0 | L31: =IF(E31>G31,E31-G31,) -> 34 | M31: =L31/E31 -> 1 | N31: =L31*C31 -> 48546.9
A32: 1.27 | B32: Painting the walls with two coats of oil bound distemper over one coat of water based cement primer including cost of distemper, primer, cleaning, scrabbing the walls, rendering the walls smooth with necessary putty, brushes, scaffolding arrangements, labour charges etc., complete, complying standard specification and as directed. ( The quality and colour of oil bound distemper should got approved by the Executive Engineer before use.) | C32: 197.75 | D32: M2 | E32: 1865 | F32: =C32*E32 -> 368803.75 | G32: ='Bill Abs'!C34 -> 0 | H32: =G32*C32 -> 0 | I32: =IF(E32<G32,G32-E32,) -> 0 | J32: =I32/E32 -> 0 | K32: =I32*C32 -> 0 | L32: =IF(E32>G32,E32-G32,) -> 1865 | M32: =L32/E32 -> 1 | N32: =L32*C32 -> 368803.75
A33: 1.28 | B33: Supplying and fixing of 40 X 6mm G.I Flat over the galvalume sheet roofing which is placed on the top of Purlin in the longitudinal direction to avoid the lifting of roofing during heavy wind. The rate is inclusive of GI screws 75mm length with rubber and aluminium washer, drilling hole over GI Flat to hold the sheet and purlin with necessary adhesive flashing tap directly over the galvalume sheet including labour charges for fixing, conveyance, loading, unloading and cutting etc. complete as directed by the departmental officers. | C33: 241.35 | D33: RM | E33: 842 | F33: =C33*E33 -> 203216.7 | G33: ='Bill Abs'!C35 -> 0 | H33: =G33*C33 -> 0 | I33: =IF(E33<G33,G33-E33,) -> 0 | J33: =I33/E33 -> 0 | K33: =I33*C33 -> 0 | L33: =IF(E33>G33,E33-G33,) -> 842 | M33: =L33/E33 -> 1 | N33: =L33*C33 -> 203216.7
A34: 1.29 | B34: Supplying fabricating, hoisting and erection of ROOF TRUSSES PURLINS AND WIND BRACING with structural steel member like angle and channel iron and M.S.plates for all truss, purlin members including all cutting drilling holes, and welding and fixing of member with necessary bolts and nuts, of approved quality and hoisting, aligning and placing the trusses in position etc., complete the trusses will be manufactured as per the detailed plan. The rate should include the cost of painting with one coat of red oxide primer with two coats of best quality of aluminium paint over priming coat. | C34: =145.2 -> 145.2 | D34: Kg | E34: 35811 | F34: =C34*E34 -> 5199757.2 | G34: ='Bill Abs'!C36 -> 35731 | H34: =G34*C34*0.7 -> 3631698.8 | I34: =IF(E34<G34,G34-E34,) -> 0 | J34: =I34/E34 -> 0 | K34: =I34*C34 -> 0 | L34: =IF(E34>G34,E34-G34,) -> 80 | M34: =L34/E34 -> 0.0022339505 | N34: =L34*C34 -> 11616
A35: 1.3 | B35: Reinforcement Cement Concrete 1:1 ½ :3 ( one cement, one and half sand, three aggregate) using 20mm of hard broken granite stone for all RCC works using machine for mixing concrete excluding cost of centering, Strutting, shuttering, and fabrication of reinforcement and placing the grills in position etc., but including finishing and curing etc., complete complying with standard specifications and as directed. In foundation and basement | C35: 12500.45 | D35: M3 | E35: 154 | F35: =C35*E35 -> 1925069.3 | G35: ='Bill Abs'!C37 -> 230.03 | H35: =G35*C35 -> 2875478.5 | I35: =IF(E35<G35,G35-E35,) -> 76.03 | J35: =I35/E35 -> 0.4937013 | K35: =I35*C35 -> 950409.21 | L35: =IF(E35>G35,E35-G35,) -> 0 | M35: =L35/E35 -> 0 | N35: =L35*C35 -> 0
A36: 1.31 | B36: In ground floor Upto 4.50M height above basement. | C36: 12668.25 | D36: M3 | E36: 72 | F36: =C36*E36 -> 912114 | G36: ='Bill Abs'!C38 -> 81.88 | H36: =G36*C36 -> 1037276.3 | I36: =IF(E36<G36,G36-E36,) -> 9.88 | J36: =I36/E36 -> 0.13722222 | K36: =I36*C36 -> 125162.31 | L36: =IF(E36>G36,E36-G36,) -> 0 | M36: =L36/E36 -> 0 | N36: =L36*C36 -> 0
A37: 1.32 | B37: Above 4.50M height from basement | C37: 12998.75 | D37: M3 | E37: 69 | F37: =C37*E37 -> 896913.75 | G37: ='Bill Abs'!C39 -> 64.19 | H37: =G37*C37 -> 834389.76 | I37: =IF(E37<G37,G37-E37,) -> 0 | J37: =I37/E37 -> 0 | K37: =I37*C37 -> 0 | L37: =IF(E37>G37,E37-G37,) -> 4.81 | M37: =L37/E37 -> 0.069710145 | N37: =L37*C37 -> 62523.988
A38: 1.33 | B38: Supplying and filling in foundation, basement, etc., with filling crushed stone sand in layers of not more than 15cm thick well watered, rammed and consolidated etc., complete complying with standard specification and as directed by the departmental officers. | C38: 3455.65 | D38: M3 | E38: 16 | F38: =C38*E38 -> 55290.4 | G38: ='Bill Abs'!C40 -> 0 | H38: =G38*C38 -> 0 | I38: =IF(E38<G38,G38-E38,) -> 0 | J38: =I38/E38 -> 0 | K38: =I38*C38 -> 0 | L38: =IF(E38>G38,E38-G38,) -> 16 | M38: =L38/E38 -> 1 | N38: =L38*C38 -> 55290.4
A39: 1.34 | B39: Cement Concrete 1:2:4 ( one cement, two sand, four aggregate) using 20mm of hard broken granite stone for all RCC works using machine for mixing concrete excluding cost of centering, Strutting, shuttering, and fabrication of reinforcement and placing the grills in position etc., but including finishing and curing etc., complete complying with standard specifications and as directed. In foundation basement | C39: 11812.25 | D39: M3 | E39: 6 | F39: =C39*E39 -> 70873.5 | G39: ='Bill Abs'!C41 -> 0 | H39: =G39*C39 -> 0 | I39: =IF(E39<G39,G39-E39,) -> 0 | J39: =I39/E39 -> 0 | K39: =I39*C39 -> 0 | L39: =IF(E39>G39,E39-G39,) -> 6 | M39: =L39/E39 -> 1 | N39: =L39*C39 -> 70873.5
A40: 1.35 | B40: In ground floor upto 4.50M height above basement | C40: 11980 | D40: M3 | E40: 5 | F40: =C40*E40 -> 59900 | G40: ='Bill Abs'!C42 -> 0 | H40: =G40*C40 -> 0 | I40: =IF(E40<G40,G40-E40,) -> 0 | J40: =I40/E40 -> 0 | K40: =I40*C40 -> 0 | L40: =IF(E40>G40,E40-G40,) -> 5 | M40: =L40/E40 -> 1 | N40: =L40*C40 -> 59900
...

Sheet Bill Abs
A1: LS 2nd & Part Bill
A2: =Comparative!A2 -> Name of Work :Construction of New Taluk operational godown of 2500M.T(1X1500MT, 1X1000MT) capacity in TNCSC campus at Survey No.2347/1 to an extent of 1.21.44 Hectare at Nelliyalam Village in Pandalur Taluk in Nilgiris District.
B3: =Comparative!B3 -> 450 | E3: =Comparative!E3 -> 3622324 | H3: =Comparative!H3 -> 1752324
B4: Name of the Contractor:- M/s .Romaa Housing Pvt Ltd, Chennai. | E4: Date of commencement : 12 .09 .2024 | H4: Agreement Period : 12 months Probable Completion : 30.6.2024
A5: S.NO | B5: DISCRIPTION OF WORK | C5: Total Qty Upto date | E5: Agt Rate | F5: Total Value Upto Date (In Rupees) | G5: Deduct Previous Bill Amount | J5: Since Last Measurements | M5: Agreement Qty
C6: Qty | D6: Unit | G6: M.Book/ Pg | H6: Qty | I6: Ampount (in Rupees) | J6: QTY | K6: Unit | L6: Amount (in Rupees)
A7: 1 | B7: 2 | C7: 3 | D7: 4 | E7: 5 | F7: 6 | G7: 7 | H7: 8 | I7: 9 | J7: 10 | K7: 11 | L7: 12 | M7: 13
A8: 1.01 | B8: Clearing Scrub Jungle as directed by the departmental officers. | C8: =H8+J8 -> 4000 | D8: M2 | E8: 7.55 | F8: =C8*E8 -> 30200 | G8: 6981ACE/1 | H8: 4000 | I8: =H8*E8 -> 30200 | K8: M2 | L8: =J8*E8 -> 0 | M8: 4000
A9: 1.02 | B9: EARTH WORK excavation for foundation in all classes of soils and subsoils to full depth, as may be directed except in hard rock, requiring blasting including initial leads and lifts and refilling the sides of foundation with excavated earth in 150mm layers well watered rammed and consolidated including depositing surplus earth with in the Godown or inside compound in places shown with initial leads and lifts, clearing, leveling site, shoring, strutting, baling of water wherever necessary etc., complete complying with standard specification and as directed. | C9: =H9+J9 -> 566.32 | D9: M3 | E9: 279.85 | F9: =C9*E9 -> 158484.65 | G9: 6981ACE/1 | H9: 566.32 | I9: =H9*E9 -> 158484.65 | K9: M3 | L9: =J9*E9 -> 0 | M9: 447
A10: 1.03 | B10: Refilling with excavated earth in basement including watering, rammed and consolidated etc., complete complying with standard specifications and as directed. | C10: =H10+J10 -> 269.33 | D10: M3 | E10: 54.55 | F10: =C10*E10 -> 14691.951 | G10: 6981ACE/2 | H10: 269.33 | I10: =H10*E10 -> 14691.951 | K10: M3 | L10: =J10*E10 -> 0 | M10: 273
A11: 1.04 | B11: Supplying and filling in foundation with Gravel in layers of not exceeding 150mm thick well watered, rammed and consolidated including watering etc., complete complying with standard specification and as directed. | C11: =H11+J11 -> 927.68 | D11: M3 | E11: 2347 | F11: =C11*E11 -> 2177265 | G11: 6981ACE/2 | H11: 927.68 | I11: =H11*E11 -> 2177265 | K11: M3 | L11: =J11*E11 -> 0 | M11: 450
A12: 1.05 | B12: Refilling with conveyed earth to a lead of 10KM for filling in foundation and basement including watering, rammed and consolidated etc., complete and as directed by the departmental officers. | C12: =H12+J12 -> 822.94 | D12: M3 | E12: 278.3 | F12: =C12*E12 -> 229024.2 | G12: 6981ACE/2 | H12: 822.94 | I12: =H12*E12 -> 229024.2 | K12: M3 | L12: =J12*E12 -> 0 | M12: 824
A13: 1.06 | B13: Supplying and filling in basement with wetmix 250mm thick in layers of not exceeding 250mm thick, well watered, rammed and consolidated including machineries for hire and running charges leader 5 Cum capacity, hire charges for tipper, water sprinkler,` vibratory roller all labour charges etc., complete complying with standard specification and as directed | C13: =H13+J13 -> 209.48 | D13: M3 | E13: 4269.95 | F13: =C13*E13 -> 894469.13 | G13: 0 | I13: =H13*E13 -> 0 | J13: ='Pandalur Dt Wise'!I261 -> 209.48 | K13: M3 | L13: =J13*E13 -> 894469.13 | M13: 300
A14: 1.07 | B14: CEMENT CONCRETE 1:5:10(one cement , five sand and ten aggregate)using 40mm gauge hard broken granite stone jelly for foundation including de-watering side shuttering , strutting, wherever necessary including curing etc., complete complying with standard specifications and as directed. | C14: =H14+J14 -> 173.76 | D14: M3 | E14: 8093 | F14: =C14*E14 -> 1406239.7 | G14: 6981ACE/3 | H14: 16.65 | I14: =H14*E14 -> 134748.45 | J14: ='Pandalur Dt Wise'!I274 -> 157.11 | K14: M3 | L14: =J14*E14 -> 1271491.2 | M14: 270
A15: 1.08 | B15: BRICK WORK in cement mortar 1:5(One cement ,Five sand)using best quality Country Bricks of size 8 ¾”x4 ¼” x2¼’’ for walls including cost of scaffolding curing ,finishing etc., complete complying with standard specifications and as directed. In foundation and basement. | C15: =H15+J15 -> 181.41 | D15: M3 | E15: 7536.75 | F15: =C15*E15 -> 1367241.8 | G15: 6981ACE/3 | H15: 181.41 | I15: =H15*E15 -> 1367241.8 | K15: M3 | L15: =J15*E15 -> 0 | M15: 141
A16: 1.09 | B16: In ground floor Upto 4.50M height above basement. | C16: =H16+J16 -> 247.35 | D16: M3 | E16: 7647.2 | F16: =C16*E16 -> 1891534.9 | G16: 0 | I16: =H16*E16 -> 0 | J16: ='Pandalur Dt Wise'!I136 -> 247.35 | K16: M3 | L16: =J16*E16 -> 1891534.9 | M16: 243
A17: 1.1 | B17: Above 4.50M height above basement. | C17: =H17+J17 -> 81.18 | D17: M3 | E17: 7870.19 | F17: =C17*E17 -> 638902.02 | G17: 0 | I17: =H17*E17 -> 0 | J17: ='Pandalur Dt Wise'!I206 -> 81.18 | K17: M3 | L17: =J17*E17 -> 638902.02 | M17: 103
A18: 1.11 | B18: Providing FORM WORK for centering the soffits of all reinforcement concrete work including strutting to the required (3 metre) height with mild-steel sheets of size 90cmx60cm 10 gauge stiffened with welded mild steel angles of size 25mmx25mmx3mm laid with country wood joist of average of size 10cmx6.50cm at about 90cm centres with casurina props of 13cm dia at 75cm centre to centre with all nails coir,wedges complete and removing the form work after necessary curing period as directed by the corporations officers. The rates should inclusives of cutting , bending, welding , charges of M.S sheets, M.S. angles etc., Complete Column footing, Plinth beam, top tie beame | C18: =H18+J18 -> 743.97 | D18: M2 | E18: 1159.9 | F18: =C18*E18 -> 862930.8 | G18: 6981ACE/4 | H18: 580.51 | I18: =H18*E18 -> 673333.55 | J18: ='Pandalur Dt Wise'!I12 -> 163.46 | K18: M2 | L18: =J18*E18 -> 189597.25 | M18: 715
A19: 1.12 | B19: Rectangular beams and floor slabs, tie beams, lintels, landing slab, loft etc., | C19: =H19+J19 -> 661.02 | D19: M2 | E19: 1278.8 | F19: =C19*E19 -> 845312.38 | G19: 0 | I19: =H19*E19 -> 0 | J19: ='Pandalur Dt Wise'!I164+'Pandalur Dt Wise'!I231 -> 661.02 | K19: M2 | L19: =J19*E19 -> 845312.38 | M19: 805
A20: 1.13 | B20: Column, ratguard slab, curtain slab and sun shades etc., | C20: =H20+J20 -> 953.6 | D20: M2 | E20: 1406.65 | F20: =C20*E20 -> 1341381.4 | G20: 6981ACE/5 | H20: 257.36 | I20: =H20*E20 -> 362015.44 | J20: ='Pandalur Dt Wise'!I37+'Pandalur Dt Wise'!I86 -> 696.24 | K20: M2 | L20: =J20*E20 -> 979366 | M20: 906
A21: 1.14 | B21: Supplying, fabricating and placing in position MS/RTS grills for reinforcement for all R.C.C.works including cost of steel, labour for straightening, bending, cranking, tying grills with 18 gauge galvanized binding wire and placing grills in position complete complying with standard specification and as directed.. | C21: =H21+J21 -> 388.26122 | D21: QTL | E21: 10099.75 | F21: =C21*E21 -> 3921341.3 | G21: 6981ACE/5 | H21: 162.1 | I21: =H21*E21 -> 1637169.5 | J21: ='Steel 1500MT'!K114 -> 226.16122 | K21: QTL | L21: =J21*E21 -> 2284171.8 | M21: 524.6
A22: 1.15 | B22: Supplying and fixing (under lintel grove) cold rolled ROLLING SHUTTERS of approved quality of 18 gauge 7.5 cm wide cold rolled lathe section in one piece interlocked together with specially designed pipe shaft with adequate number of high tensile steels wire springs of approved quality complete with brackets side guides and arrangements for inside and outside locking arrangements with push and pull operations and pulling back handle with all accessories without workmanship and the entire shutter painted with two coats of best quality anti-corrosive nut brown color paint over one coat of red oxide primer and clear opening of 1.8 M width 2.60 M | C22: =H22+J22 -> 12 | D22: NOS | E22: 14635 | F22: =C22*E22 -> 175620 | G22: 0 | I22: =H22*E22 -> 0 | J22: ='Pandalur Dt Wise'!I267 -> 12 | K22: NOS | L22: =J22*E22 -> 175620 | M22: 10
A23: 1.16 | B23: Supplying and fixing of Steel glazed AIR INLET WINDOWs of size 0.6m x 0.6m using extruded angles (Z-section) alround for frame with centre mullion (T-section) and shutter with the same Z-section properly fixed with hinges 2 nos. for each shutter. The panel of shutter fixed with G.I. sheet of'18 gauge and necessary locking arrangements including weld mesh cover using weld mesh 25mm x 25mm x 10mm gauge and welded with iron square bars of 10mm size - 3nos. horizontally and 2nos. vertically welded together to form a grill and welding grill to the main frame with 4mm thick and 12mm wide MS flats. The rate is also inclusive of one coat of steel primer and two coats of ANTI CORROSIVE METALLIC paint and quality, 2 nos. | C23: =H23+J23 -> 34 | D23: NOS | E23: 3453.2 | F23: =C23*E23 -> 117408.8 | G23: 0 | I23: =H23*E23 -> 0 | J23: ='Pandalur Dt Wise'!I280 -> 34 | K23: NOS | L23: =J23*E23 -> 117408.8 | M23: 36
A24: 1.17 | B24: Supplying and fixing steel N-Type VENTILATOR of size 2.60m x 0.60m using extruded angle (Z-section 25mmx25mmx3mm) for outer frames with center mullion (T-section)and with weld mesh of 25mmx25mm 10guage on all three sides ( 2 verticals 1 horizontal) and 10mm size MS square bars horizontally one at top and one at bottom welded to the frames with necessary MS flats of size 20mmx4mm thick | C24: =H24+J24 -> 92 | D24: NOS | E24: 4250 | F24: =C24*E24 -> 391000 | G24: 0 | I24: =H24*E24 -> 0 | J24: ='Pandalur Dt Wise'!I286 -> 92 | K24: NOS | L24: =J24*E24 -> 391000 | M24: 92
A25: 1.18 | B25: Providing vacuum de watered controlled cement surfacing 100mm thick in required slope and chamber confirming M20 grade with 20mm size stone aggregate cast in situ ,smooth finish and leveling with double framed screed vibrator ,excess water to be removed through vacuum pump with bottom and top filter mat duly sealing the edges all round including provisions of polythene sheet below the concrete layer before placing of concrete and finishing with paver floated and power trawler to obtain the hard surface including provision of expansion joints at 6mtr intervals across the platform by cutting 6mm wide and full depth of concrete by contractors | C25: =H25+J25 -> 0 | D25: M2 | E25: 1653.4 | F25: =C25*E25 -> 0 | G25: 0 | I25: =H25*E25 -> 0 | K25: M2 | L25: =J25*E25 -> 0 | M25: 1503
A26: 1.19 | B26: PLASTERING with cement mortor 1:5 (one cement and five sand) 12mm thick including cost of scaffolding, finishing, curing etc., complete complying with standard specification and as directed. | C26: =H26+J26 -> 1480.4 | D26: M2 | E26: 356.05 | F26: =C26*E26 -> 527096.42 | G26: 0 | I26: =H26*E26 -> 0 | J26: ='Pandalur Dt Wise'!I413 -> 1480.4 | K26: M2 | L26: =J26*E26 -> 527096.42 | M26: 3522
A27: 1.2 | B27: PLASTERING with the exposed RCC surface with C.M.1:3(one cement and three sand) 10mm thick including cost of scaffolding, finishing, curing etc., complete complying with standard Specification and as directed. | C27: =H27+J27 -> 539.81 | D27: M2 | E27: 401.1 | F27: =C27*E27 -> 216517.79 | G27: 0 | I27: =H27*E27 -> 0 | J27: ='Pandalur Dt Wise'!I434 -> 539.81 | K27: M2 | L27: =J27*E27 -> 216517.79 | M27: 1350
A28: 1.21 | B28: Painting the walls with two coats of exterior emulsion paint of first class approved quality and colour over a priming coat including thorough scrapping, clean removal of dirt, and including necessary plaster of paris putty, wherever required etc., complete complying with standard specification and as directed. | C28: =H28+J28 -> 0 | D28: M2 | E28: 309.2 | F28: =C28*E28 -> 0 | G28: 0 | I28: =H28*E28 -> 0 | K28: M2 | L28: =J28*E28 -> 0 | M28: 3209
A29: 1.22 | B29: Supplying, fabricating and fixing in position M.S.Channel 100x50x6mm at the edge of loading platform with M.S bolt of 16mm at the edge of loading platform with M.S bolt of 16mm at the edge of loading platform finishing in flush with the slab with C.M 1:3 complete including painting the exposed surface of MS channel with two coats of ANI Corrosive metalic net brown colour paint over one coat red oxide primer etc., complete. | C29: =H29+J29 -> 81.5 | D29: RM | E29: 1277 | F29: =C29*E29 -> 104075.5 | G29: 0 | I29: =H29*E29 -> 0 | J29: ='Pandalur Dt Wise'!I51 -> 81.5 | K29: RM | L29: =J29*E29 -> 104075.5 | M29: 76.4
A30: 1.23 | B30: Supplying and fixing of Rotary Ventilators over the roof with necessary bolt and nut arrangement to withstand the wind velocity as specified by the departmental officers. (Size 600mm x 600mm) | C30: =H30+J30 -> 0 | D30: NOS | E30: 18000 | F30: =C30*E30 -> 0 | G30: 0 | I30: =H30*E30 -> 0 | K30: NOS | L30: =J30*E30 -> 0 | M30: 11
A31: 1.24 | B31: Supplying and laying of profiled colour galvalume sheet with combination 55A1:43 4Zn:1:6SI of TCT bent type 0.47mm thick and standard width of 1.06m with yield strength of 550 MPA made from high tensile/ CR sheets of approved quality for roofing with necessary fixing arrangements like 65m abd long hexagonal head screws with EPDM rubber seal etc., complete complying with standard specification and as directed by the departmental officer. (Test certificate for quality should be furnished on receipt of material at site) | C31: =H31+J31 -> 1897.96 | D31: M2 | E31: =1198.15*0.7 -> 838.705 | F31: =C31*E31 -> 1591828.5 | G31: 0 | I31: =H31*E31 -> 0 | J31: ='Pandalur Dt Wise'!I445 -> 1897.96 | K31: M2 | L31: =J31*E31 -> 1591828.5 | M31: 1911
A32: 1.25 | B32: Supplying and roofing with Galvalume sheet ridge pieces of size 1.00M x 0.7M, 0.47mm thick with necessary U or J bolt and nuts G.I washers etc., complete For the above works skilled man power, necessary tools, equipments, power supply, water supply including transport, any other statuary approval required for the transporting the materials shall be duly obtained by the contractor. (Test certificate for quality should be furnished on receipt of material at site) | C32: =H32+J32 -> 105.92 | D32: RM | E32: =656.5*0.7 -> 459.55 | F32: =C32*E32 -> 48675.536 | G32: 0 | I32: =H32*E32 -> 0 | J32: ='Pandalur Dt Wise'!I451 -> 105.92 | K32: RM | L32: =J32*E32 -> 48675.536 | M32: 107
A33: 1.26 | B33: Supplying and fixing corrugated Poly Carbonate sheet of size 3mx1.06m of 3mm thick on the roof in-between the colour coated Galvalume sheets for proper lighting with necessary G.I screws and EPDM rubber washers, Complying with standard specification and as direct and specified by the departmental officers including cost of loading unloading and transportion charges etc., complete. | C33: =H33+J33 -> 0 | D33: M2 | E33: 1427.85 | F33: =C33*E33 -> 0 | G33: 0 | I33: =H33*E33 -> 0 | K33: M2 | L33: =J33*E33 -> 0 | M33: 34
A34: 1.27 | B34: Painting the walls with two coats of oil bound distemper over one coat of water based cement primer including cost of distemper, primer, cleaning, scrabbing the walls, rendering the walls smooth with necessary putty, brushes, scaffolding arrangements, labour charges etc., complete, complying standard specification and as directed. ( The quality and colour of oil bound distemper should got approved by the Executive Engineer before use.) | C34: =H34+J34 -> 0 | D34: M2 | E34: 197.75 | F34: =C34*E34 -> 0 | G34: 0 | I34: =H34*E34 -> 0 | K34: M2 | L34: =J34*E34 -> 0 | M34: 1865
A35: 1.28 | B35: Supplying and fixing of 40 X 6mm G.I Flat over the galvalume sheet roofing which is placed on the top of Purlin in the longitudinal direction to avoid the lifting of roofing during heavy wind. The rate is inclusive of GI screws 75mm length with rubber and aluminium washer, drilling hole over GI Flat to hold the sheet and purlin with necessary adhesive flashing tap directly over the galvalume sheet including labour charges for fixing, conveyance, loading, unloading and cutting etc. complete as directed by the departmental officers. | C35: =H35+J35 -> 0 | D35: RM | E35: 241.35 | F35: =C35*E35 -> 0 | G35: 0 | I35: =H35*E35 -> 0 | K35: RM | L35: =J35*E35 -> 0 | M35: 842
A36: 1.29 | B36: Supplying fabricating, hoisting and erection of ROOF TRUSSES PURLINS AND WIND BRACING with structural steel member like angle and channel iron and M.S.plates for all truss, purlin members including all cutting drilling holes, and welding and fixing of member with necessary bolts and nuts, of approved quality and hoisting, aligning and placing the trusses in position etc., complete the trusses will be manufactured as per the detailed plan. The rate should include the cost of painting with one coat of red oxide primer with two coats of best quality of aluminium paint over priming coat. | C36: =H36+J36 -> 35731 | D36: Kg | E36: =145.2*0.7 -> 101.64 | F36: =C36*E36 -> 3631698.8 | G36: 0 | I36: =H36*E36 -> 0 | J36: ='Pandalur Dt Wise'!I366 -> 35731 | K36: Kg | L36: =J36*E36 -> 3631698.8 | M36: 35811
A37: 1.3 | B37: Reinforcement Cement Concrete 1:1 ½ :3 ( one cement, one and half sand, three aggregate) using 20mm of hard broken granite stone for all RCC works using machine for mixing concrete excluding cost of centering, Strutting, shuttering, and fabrication of reinforcement and placing the grills in position etc., but including finishing and curing etc., complete complying with standard specifications and as directed. In foundation and basement | C37: =H37+J37 -> 230.03 | D37: M3 | E37: 12500.45 | F37: =C37*E37 -> 2875478.5 | G37: 6981ACE/6 | H37: 177.7 | I37: =H37*E37 -> 2221330 | J37: ='Pandalur Dt Wise'!I67 -> 52.33 | K37: M3 | L37: =J37*E37 -> 654148.55 | M37: 154
A38: 1.31 | B38: In ground floor Upto 4.50M height above basement. | C38: =H38+J38 -> 81.88 | D38: M3 | E38: 12668.25 | F38: =C38*E38 -> 1037276.3 | G38: 0 | I38: =H38*E38 -> 0 | J38: =+'Pandalur Dt Wise'!I96+'Pandalur Dt Wise'!I187 -> 81.88 | K38: M3 | L38: =J38*E38 -> 1037276.3 | M38: 72
A39: 1.32 | B39: Above 4.50M height from basement | C39: =H39+J39 -> 64.19 | D39: M3 | E39: 12998.75 | F39: =C39*E39 -> 834389.76 | G39: 0 | I39: =H39*E39 -> 0 | J39: ='Pandalur Dt Wise'!I106+'Pandalur Dt Wise'!I254 -> 64.19 | K39: M3 | L39: =J39*E39 -> 834389.76 | M39: 69
A40: 1.33 | B40: Supplying and filling in foundation, basement, etc., with filling crushed stone sand in layers of not more than 15cm thick well watered, rammed and consolidated etc., complete complying with standard specification and as directed by the departmental officers. | C40: =H40+J40 -> 0 | D40: M3 | E40: 3455.65 | F40: =C40*E40 -> 0 | G40: 0 | I40: =H40*E40 -> 0 | K40: M3 | L40: =J40*E40 -> 0 | M40: 16
...

Sheet Set
A1: =Comparative!A2 -> Name of Work :Construction of New Taluk operational godown of 2500M.T(1X1500MT, 1X1000MT) capacity in TNCSC campus at Survey No.2347/1 to an extent of 1.21.44 Hectare at Nelliyalam Village in Pandalur Taluk in Nilgiris District.
B2: LS Ist & Part Bill | D2: Date of Agt: | E2: 45344
B3: Estimate Amount : 450 Lakhs | D3: Agt Period: | E3: 12 Months
B4: C.E(R) No. 74 /2023-2024 | D4: DOC :
B5: AGT.No: 362/2023-2024 | D5: DOC :
A6: Set No | B6: Description | C6: M.Book Page | D6: AE | E6: AEE

Sheet Pandalur Dt Wise
A1: Pandalur | C1: RA - 02 Details
A2: S.no | B2: Description | C2: No | F2: L | G2: B | H2: D | I2: Qty | J2: Unit
B3: 1
A4: 1.11 | B4: Providing FORM WORK for centering the soffits of all reinforcement concrete work including strutting to the required (3 metre) height with mild steel sheets of size 90cm x60cm 10gauge stiffened with welded mild steel angles of size 25mm x 25mm x 3mm laid with coundry wood joist of average of size 10cm x 6.50cm at about 90cm centres with casurina props of 13cm dia at 75cm centre to centre with all nails coir,wedges complete and removing the form work after necessary curing period as directed by the corporations officers. The rates should inclusive of cutting, bending,welding charges of M.S.sheets, M.S.angles.
B5: Plinth Beam
B6: 1000MT
B7: Panel Wall | C7: 2 | D7: X | E7: 2 | F7: 42.46 | G7: - | H7: 0.3 | I7: =ROUND(PRODUCT(C7:H7),2) -> 50.95
B8: Cable Wall | C8: 2 | D8: X | E8: 2 | F8: 15.15 | G8: - | H8: 0.3 | I8: =ROUND(PRODUCT(C8:H8),2) -> 18.18
B9: 1500MT
B10: Panel Wall | C10: 2 | D10: X | E10: 2 | F10: 63.46 | G10: - | H10: 0.3 | I10: =ROUND(PRODUCT(C10:H10),2) -> 76.15
B11: Cable Wall | C11: 2 | D11: X | E11: 2 | F11: 15.15 | G11: - | H11: 0.3 | I11: =ROUND(PRODUCT(C11:H11),2) -> 18.18
B12: Total | I12: =ROUND(SUM(I7:I11),2) -> 163.46 | J12: M2
A13: 1.13 | B13: Providing FORM WORK for centering the soffits of all reinforcement concrete work including strutting to the required (3 metre) height with mild steel sheets of size 90cm x60cm 10gauge stiffened with welded mild steel angles of size 25mm x 25mm x 3mm laid with coundry wood joist of average of size 10cm x 6.50cm at about 90cm centres with casurina props of 13cm dia at 75cm centre to centre with all nails coir,wedges complete and removing the form work after necessary curing period as directed by the corporations officers. The rates should inclusive of cutting, bending,welding charges of M.S.sheets, M.S.angles.
B14: 1000MT
B15: loading platform
B16: loading platform bottom | C16: 2 | D16: X | E16: 4 | F16: 5.85+4.85 2 | G16: 1 | H16: - | I16: =2*4*5.35*1 -> 42.8
B17: Curtain slab inner side | C17: 1 | D17: X | E17: 4 | F17: 2.1 | G17: - | H17: 0.45 | I17: =ROUND(PRODUCT(C17:H17),2) -> 3.78
B18: Curtain slab outer side | C18: 1 | D18: X | E18: 4 | F18: 2.1 | G18: - | H18: 0.35 | I18: =ROUND(PRODUCT(C18:H18),2) -> 2.94
B19: Rat guard slab bottom panel wall
B20: both sides | C20: 2 | D20: X | E20: 1 | F20: 42.46 | G20: 0.3 | H20: - | I20: =ROUND(PRODUCT(C20:H20),2) -> 25.48
B21: Rat guard slab vertical face | C21: 2 | D21: X | E21: 1 | F21: 42.46 | G21: - | H21: 0.05 | I21: =ROUND(PRODUCT(C21:H21),2) -> 4.25
B22: Rat guard slab cable wall bottom | C22: 2 | D22: X | E22: 1 | F22: 15.15 | G22: 0.3 | H22: - | I22: =ROUND(PRODUCT(C22:H22),2) -> 9.09
B23: Rat guard slab vertical face | C23: 2 | D23: X | E23: 1 | F23: 15.31 | G23: - | H23: 0.05 | I23: =ROUND(PRODUCT(C23:H23),2) -> 1.53
B24: Deduct loading platform portion bottom | C24: -2 | D24: X | E24: 2 | F24: 5.35 | G24: 0.3 | H24: - | I24: =ROUND(PRODUCT(C24:H24),2) -> -6.42
B25: Deduct loading platform portion vertical face | C25: -2 | D25: X | E25: 2 | F25: 5.35 | G25: - | H25: 0.05 | I25: =ROUND(PRODUCT(C25:H25),2) -> -1.07
B26: 1500MT
B27: loading platform bottom | C27: 2 | D27: X | E27: 3 | F27: 5.85+4.85 2 | G27: 1 | H27: - | I27: =2*4*5.35*1 -> 42.8
B28: Curtain slab inner side | C28: 2 | D28: X | E28: 3 | F28: 2.1 | G28: - | H28: 0.45 | I28: =ROUND(PRODUCT(C28:H28),2) -> 5.67
B29: Curtain slab outer side | C29: 2 | D29: X | E29: 3 | F29: 2.1 | G29: - | H29: 0.35 | I29: =ROUND(PRODUCT(C29:H29),2) -> 4.41
B30: Rat guard slab bottom panel wall | I30: =ROUND(PRODUCT(C30:H30),2) -> 0
B31: both sides | C31: 2 | D31: X | E31: 1 | F31: 64.15 | G31: 0.3 | H31: - | I31: =ROUND(PRODUCT(C31:H31),2) -> 38.49
B32: Rat guard slab vertical face | C32: 2 | D32: X | E32: 1 | F32: 64.15 | G32: - | H32: 0.05 | I32: =ROUND(PRODUCT(C32:H32),2) -> 6.42
B33: Rat guard slab Gable wall bottom | C33: 2 | D33: X | E33: 1 | F33: 15.15 | G33: 0.3 | H33: - | I33: =ROUND(PRODUCT(C33:H33),2) -> 9.09
B34: Rat guard slab vertical face | C34: 2 | D34: X | E34: 1 | F34: 15.61 | G34: - | H34: 0.05 | I34: =ROUND(PRODUCT(C34:H34),2) -> 1.56
B35: Deduct loading platform portion bottom | C35: -2 | D35: X | E35: 3 | F35: 5.85 | G35: 0.3 | H35: - | I35: =ROUND(PRODUCT(C35:H35),2) -> -10.53
B36: Deduct loading platform portion vertical face | C36: -2 | D36: X | E36: 3 | F36: 5.85 | G36: - | H36: 0.05 | I36: =ROUND(PRODUCT(C36:H36),2) -> -1.76
B37: Total | I37: =ROUND(SUM(I16:I36),2) -> 178.53 | J37: M2
B38: 2
A39: 1.14 | B39: Supplying, fabricating and placing in position MS/RTS grills for reinforcement for all R.C.C.works including cost of steel, labour for straightening, bending, cranking, tying grills with 18 gauge galvanized binding wire and placing grills in position complete complying with standard specification and as directed..
B40: 1000MT
...

Sheet Steel 1000MT 
A1: Pandalur Steel - BBS RA02
A2: S.no | B2: Description | C2: No's | F2: Cutting Length | G2: #8mm | H2: #10mm | I2: #12mm | J2: #16mm | K2: #20mm
G3: Total Length
B4: 2
A5: 1.14 | B5: PLINTH BEAM
B6: PB 01
B7: #12mm main bar TOP & Bot | C7: 2 | D7: X | E7: 6 | F7: 33.68 | I7: =+PRODUCT(C7:F7) -> 404.16
B8: #12mm main bar Lap | C8: 2 | D8: X | E8: =6*3 -> 18 | F8: 0.6 | I8: =+PRODUCT(C8:F8) -> 21.6
B9: #10mm Stirupps | C9: 2 | D9: X | E9: 206 | F9: 1.6 | H9: =+PRODUCT(C9:F9) -> 659.2
B10: #8mm distribution bar | C10: 2 | D10: X | E10: 3 | F10: 30.88 | G10: =+PRODUCT(C10:F10) -> 185.28
B11: #8mm distribution Lap bar | C11: 2 | D11: X | E11: =3*3 -> 9 | F11: 0.4 | G11: =+PRODUCT(C11:F11) -> 7.2
B13: PB 02 (Loading plot form)
B14: #16mm main bar Top&Bot | C14: 2 | D14: X | E14: =2*6 -> 12 | F14: 7.45 | J14: =+PRODUCT(C14:F14) -> 178.8
B15: #12mm Stirupps | C15: 2 | D15: X | E15: =2*59 -> 118 | F15: 2.23 | I15: =+PRODUCT(C15:F15) -> 526.28
B16: #12mm main bar | C16: 2 | D16: X | E16: =2*59 -> 118 | F16: 1.3 | I16: =+PRODUCT(C16:F16) -> 306.8
B17: #12mm distribution Top | C17: 2 | D17: X | E17: =2*11 -> 22 | F17: 5.35 | I17: =+PRODUCT(C17:F17) -> 235.4
B18: #12mm distribution Bot | C18: 2 | D18: X | E18: =2*9 -> 18 | F18: 5.35 | I18: =+PRODUCT(C18:F18) -> 192.6
B20: PB 01
B21: #12mm main bar Top&Bot | C21: 3 | D21: X | E21: =2*3 -> 6 | F21: 15.4 | I21: =+PRODUCT(C21:F21) -> 277.2
B22: #12mm main bar Lap | C22: 3 | D22: X | E22: =2*3 -> 6 | F22: 0.8 | I22: =+PRODUCT(C22:F22) -> 14.4
B23: #10mm Stirupps | C23: 3 | D23: X | E23: 101 | F23: 1.63 | H23: =+PRODUCT(C23:F23) -> 493.89
B24: #8mm distribution bar | C24: 3 | D24: X | E24: 3 | F24: 15.6 | G24: =+PRODUCT(C24:F24) -> 140.4
B25: #8mm distribution Lap | C25: 3 | D25: X | E25: 3 | F25: 0.4 | G25: =+PRODUCT(C25:F25) -> 3.6
G26: =SUM(G7:G25) -> 336.48 | H26: =SUM(H7:H25) -> 1153.09 | I26: =SUM(I7:I25) -> 1978.44 | J26: =SUM(J7:J25) -> 178.8
B27: 3
B28: Column upto Top Level
B29: C1
B30: #16mm main bar | C30: 10 | D30: X | E30: 4 | F30: 3.6 | J30: =+PRODUCT(C30:F30) -> 144
B31: #12mm main bar | C31: 10 | D31: X | E31: 6 | F31: 3.6 | I31: =+PRODUCT(C31:F31) -> 216
B32: #8mm stirupps | C32: 10 | D32: X | E32: 20 | F32: 1.3 | G32: =+PRODUCT(C32:F32) -> 260
B33: #8mm stirupps | C33: 10 | D33: X | E33: 40 | F33: 1.04 | G33: =+PRODUCT(C33:F33) -> 416
I34: =+PRODUCT(C34:F34) -> 0 | J34: =+PRODUCT(C34:F34) -> 0
B35: #16mm main bar | C35: 6 | D35: X | E35: 4 | F35: 4.6 | J35: =+PRODUCT(C35:F35) -> 110.4
B36: #12mm main bar | C36: 6 | D36: X | E36: 6 | F36: 4.6 | I36: =+PRODUCT(C36:F36) -> 165.6
B37: #8mm stirupps | C37: 6 | D37: X | E37: 26 | F37: 1.3 | G37: =+PRODUCT(C37:F37) -> 202.8
B38: #8mm stirupps | C38: 6 | D38: x | E38: 42 | F38: 1.04 | G38: =+PRODUCT(C38:F38) -> 262.08
B39: C2 | G39: =+PRODUCT(C39:F39) -> 0
B40: #16mm main bar | C40: 2 | D40: X | E40: 4 | F40: 3.6 | G40: =+PRODUCT(C40:F40) -> 28.8 | J40: =+PRODUCT(C40:F40) -> 28.8
B41: #12mm main bar | C41: 2 | D41: X | E41: 4 | F41: 3.6 | I41: =+PRODUCT(C41:F41) -> 28.8
B42: #8mm stirupps | C42: 2 | D42: X | E42: 20 | F42: 1.06 | G42: =+PRODUCT(C42:F42) -> 42.4
...

Sheet Steel 1500MT
A1: Pandalur Steel - BBS RA02
A2: S.no | B2: Description | C2: No's | F2: Cutting Length | G2: #8mm | H2: #10mm | I2: #12mm | J2: #16mm | K2: #20mm
G3: Total Length
B4: 2
A5: 1.14 | B5: PLINTH BEAM
B6: PB 01
B7: #12mm main bar TOP & Bot | C7: 2 | D7: X | E7: 6 | F7: 50.03 | I7: =+PRODUCT(C7:F7) -> 600.36
B8: #12mm main bar Lap | C8: 2 | D8: X | E8: =6*4 -> 24 | F8: 0.6 | I8: =+PRODUCT(C8:F8) -> 28.8
B9: #10mm Stirupps | C9: 2 | D9: X | E9: 307 | F9: 1.6 | H9: =+PRODUCT(C9:F9) -> 982.4
B10: #8mm distribution bar | C10: 2 | D10: X | E10: 3 | F10: 50.03 | G10: =+PRODUCT(C10:F10) -> 300.18
B11: #8mm distribution Lap bar | C11: 2 | D11: X | E11: =3*4 -> 12 | F11: 0.4 | G11: =+PRODUCT(C11:F11) -> 9.6
B13: PB 02 (Loading plot form)
B14: #16mm main bar Top&Bot | C14: 2 | D14: X | E14: =3*6 -> 18 | F14: 7.45 | J14: =+PRODUCT(C14:F14) -> 268.2
B15: #12mm Stirupps | C15: 2 | D15: X | E15: =3*59 -> 177 | F15: 2.23 | I15: =+PRODUCT(C15:F15) -> 789.42
B16: #12mm main bar | C16: 2 | D16: X | E16: =3*59 -> 177 | F16: 1.3 | I16: =+PRODUCT(C16:F16) -> 460.2
B17: #12mm distribution Top | C17: 2 | D17: X | E17: =3*11 -> 33 | F17: 5.35 | I17: =+PRODUCT(C17:F17) -> 353.1
B18: #12mm distribution Bot | C18: 2 | D18: X | E18: =3*9 -> 27 | F18: 5.35 | I18: =+PRODUCT(C18:F18) -> 288.9
B19: #16mm channel Welding bar | C19: 2 | D19: X | E19: =3*4 -> 12 | F19: 1.25 | J19: =+PRODUCT(C19:F19) -> 30
B21: PB 01
B22: #12mm main bar Top&Bot | C22: 3 | D22: X | E22: =2*3 -> 6 | F22: 15.4 | I22: =+PRODUCT(C22:F22) -> 277.2
B23: #12mm main bar Lap | C23: 3 | D23: X | E23: =2*3 -> 6 | F23: 0.8 | I23: =+PRODUCT(C23:F23) -> 14.4
B24: #10mm Stirupps | C24: 3 | D24: X | E24: 101 | F24: 1.63 | H24: =+PRODUCT(C24:F24) -> 493.89
B25: #8mm distribution bar | C25: 3 | D25: X | E25: 3 | F25: 15.6 | G25: =+PRODUCT(C25:F25) -> 140.4
B26: #8mm distribution Lap | C26: 3 | D26: X | E26: 3 | F26: 0.4 | G26: =+PRODUCT(C26:F26) -> 3.6
G27: =SUM(G7:G26) -> 453.78 | H27: =SUM(H7:H26) -> 1476.29 | I27: =SUM(I7:I26) -> 2812.38 | J27: =SUM(J7:J26) -> 298.2
G28: =G27+'Steel 1000MT '!G26 -> 790.26 | H28: =H27+'Steel 1000MT '!H26 -> 2629.38 | I28: =I27+'Steel 1000MT '!I26 -> 4790.82 | J28: =J27+'Steel 1000MT '!J26 -> 477
B29: 3
B30: Column upto Top Level
B31: C1
